<?xml version='1.0' encoding='UTF-8'?>
<mujoco model="panda">
    <compiler angle="radian" meshdir="../meshes_mujoco/"/>
    <size njmax="1400" nconmax="500"/>
    <asset>
        <mesh name="panda visual link0" file="panda visual link0.stl"/>
        <mesh name="panda collision link0" file="panda collision link0.stl"/>
        <mesh name="panda visual link1" file="panda visual link1.stl"/>
        <mesh name="panda collision link1" file="panda collision link1.stl"/>
        <mesh name="panda visual link2" file="panda visual link2.stl"/>
        <mesh name="panda collision link2" file="panda collision link2.stl"/>
        <mesh name="panda visual link3" file="panda visual link3.stl"/>
        <mesh name="panda collision link3" file="panda collision link3.stl"/>
        <mesh name="panda visual link4" file="panda visual link4.stl"/>
        <mesh name="panda collision link4" file="panda collision link4.stl"/>
        <mesh name="panda visual link5" file="panda visual link5.stl"/>
        <mesh name="panda collision link5" file="panda collision link5.stl"/>
        <mesh name="panda visual link6" file="panda visual link6.stl"/>
        <mesh name="panda collision link6" file="panda collision link6.stl"/>
        <mesh name="panda visual link7" file="panda visual link7.stl"/>
        <mesh name="panda collision link7" file="panda collision link7.stl"/>
    </asset>
    <worldbody>
        <geom type="mesh" contype="0" conaffinity="0" group="1" mesh="panda visual link0"/>
        <geom type="mesh" mesh="panda collision link0"/>
        <body name="panda_link1" pos="0 0 0.333">
            <inertial pos="0 0 0" quat="0.711549 0.00634377 -0.0131124 0.702485" mass="2.34" diaginertia="0.707137 0.703435 0.00852456"/>
            <joint name="panda_joint1" pos="0 0 0" axis="0 0 1" limited="true" range="-2.8973 2.8973" damping="1" frictionloss="0.1"/>
            <geom type="mesh" contype="0" conaffinity="0" group="1" mesh="panda visual link1"/>
            <geom type="mesh" mesh="panda collision link1"/>
            <body name="panda_link2" pos="0 0 0" quat="0.707107 -0.707107 0 0">
                <inertial pos="0 0 0" quat="-0.168175 0.828366 -0.122878 0.520027" mass="2.36" diaginertia="0.0310326 0.0283001 0.00273425"/>
                <joint name="panda_joint2" pos="0 0 0" axis="0 0 1" limited="true" range="-1.7628 1.7628" damping="1" frictionloss="0.1"/>
                <geom type="mesh" contype="0" conaffinity="0" group="1" mesh="panda visual link2"/>
                <geom type="mesh" mesh="panda collision link2"/>
                <body name="panda_link3" pos="0 -0.316 0" quat="0.707107 0.707107 0 0">
                    <inertial pos="0 0 0" quat="0.662769 -0.00678331 0.252053 0.705096" mass="2.38" diaginertia="0.0415014 0.0414793 0.00124635"/>
                    <joint name="panda_joint3" pos="0 0 0" axis="0 0 1" limited="true" range="-2.8973 2.8973" damping="1" frictionloss="0.1"/>
                    <geom type="mesh" contype="0" conaffinity="0" group="1" mesh="panda visual link3"/>
                    <geom type="mesh" mesh="panda collision link3"/>
                    <body name="panda_link4" pos="0.0825 0 0" quat="0.707107 0.707107 0 0">
                        <inertial pos="0 0 0" quat="0.65058 0.529822 -0.0962034 0.535518" mass="2.43" diaginertia="0.0349596 0.0281483 0.0106201"/>
                        <joint name="panda_joint4" pos="0 0 0" axis="0 0 1" limited="true" range="-3.0718 -0.0698" damping="1" frictionloss="0.1"/>
                        <geom type="mesh" contype="0" conaffinity="0" group="1" mesh="panda visual link4"/>
                        <geom type="mesh" mesh="panda collision link4"/>
                        <body name="panda_link5" pos="-0.0825 0.384 0" quat="0.707107 -0.707107 0 0">
                            <inertial pos="0 0 0" quat="0.987313 -0.0121954 0.0719187 -0.141037" mass="3.5" diaginertia="0.0367625 0.0288531 0.00803437"/>
                            <joint name="panda_joint5" pos="0 0 0" axis="0 0 1" limited="true" range="-2.8973 2.8973" damping="1" frictionloss="0.1"/>
                            <geom type="mesh" contype="0" conaffinity="0" group="1" mesh="panda visual link5"/>
                            <geom type="mesh" mesh="panda collision link5"/>
                            <body name="panda_link6" pos="0 0 0" quat="0.707107 0.707107 0 0">
                                <inertial pos="0 0 0" quat="0.101075 0.59332 0.0287227 0.798079" mass="1.47" diaginertia="0.00584276 0.00431037 0.00159787"/>
                                <joint name="panda_joint6" pos="0 0 0" axis="0 0 1" limited="true" range="-0.0175 3.7525" damping="1" frictionloss="0.1"/>
                                <geom type="mesh" contype="0" conaffinity="0" group="1" mesh="panda visual link6"/>
                                <geom type="mesh" mesh="panda collision link6"/>
                                <body name="panda_link7" pos="0.088 0 0" quat="0.707107 0.707107 0 0">
                                    <inertial pos="0 0 0" quat="0.992939 -0.0762041 0.0733595 -0.0537067" mass="0.45" diaginertia="0.0127345 0.0101055 0.00451803"/>
                                    <joint name="panda_joint7" pos="0 0 0" axis="0 0 1" limited="true" range="-2.8973 2.8973" damping="1" frictionloss="0.1"/>
                                    <geom type="mesh" contype="0" conaffinity="0" group="1" mesh="panda visual link7"/>
                                    <geom type="mesh" mesh="panda collision link7"/>
                                </body>
                            </body>
                        </body>
                    </body>
                </body>
            </body>
        </body>
    </worldbody>
<keyframe>
    <key name="initial pose" time="0" qpos="0.01 0.02 0.03 0.04 0.05 1.0 0.07"/>
  </keyframe><actuator>
    
  <motor name="panda_joint1_actuator" joint="panda_joint1"/>

  <motor name="panda_joint2_actuator" joint="panda_joint2"/>

  <motor name="panda_joint3_actuator" joint="panda_joint3"/>

  <motor name="panda_joint4_actuator" joint="panda_joint4"/>

  <motor name="panda_joint5_actuator" joint="panda_joint5"/>

  <motor name="panda_joint6_actuator" joint="panda_joint6"/>

  <motor name="panda_joint7_actuator" joint="panda_joint7"/>

  </actuator></mujoco>