<?xml version='1.0' encoding='UTF-8'?>
<mujoco model="panda_and_gripper">
    <compiler angle="radian" meshdir="./meshes_mujoco/"/>
    <size njmax="3000" nconmax="800"/>
    <asset>
        <mesh name="panda visual link0" file="panda visual link0.stl"/>
        <mesh name="panda collision link0" file="panda collision link0.stl"/>
        <mesh name="panda visual link1" file="panda visual link1.stl"/>
        <mesh name="panda collision link1" file="panda collision link1.stl"/>
        <mesh name="panda visual link2" file="panda visual link2.stl"/>
        <mesh name="panda collision link2" file="panda collision link2.stl"/>
        <mesh name="panda visual link3" file="panda visual link3.stl"/>
        <mesh name="panda collision link3" file="panda collision link3.stl"/>
        <mesh name="panda visual link4" file="panda visual link4.stl"/>
        <mesh name="panda collision link4" file="panda collision link4.stl"/>
        <mesh name="panda visual link5" file="panda visual link5.stl"/>
        <mesh name="panda collision link5" file="panda collision link5.stl"/>
        <mesh name="panda visual link6" file="panda visual link6.stl"/>
        <mesh name="panda collision link6" file="panda collision link6.stl"/>
        <mesh name="panda visual link7" file="panda visual link7.stl"/>
        <mesh name="panda collision link7" file="panda collision link7.stl"/>
        <mesh name="main body visual" file="main body visual.STL"/>
        <mesh name="nut visual" file="nut visual.STL"/>
        <mesh name="nut collision" file="nut collision.STL"/>
        <mesh name="platform only visual" file="platform only visual.STL"/>
        <mesh name="platform only collision" file="platform only collision.STL"/>
        <mesh name="palm visual" file="palm visual.STL"/>
        <mesh name="palm collision" file="palm collision.STL"/>
    </asset>
    <worldbody>
        <geom type="mesh" contype="0" conaffinity="0" group="1" mesh="panda visual link0"/>
        <geom type="mesh" mesh="panda collision link0"/>
        <body name="panda_link1" pos="0 0 0.333">
            <inertial pos="0 0 0" quat="0.711549 0.00634377 -0.0131124 0.702485" mass="2.34" diaginertia="0.707137 0.703435 0.00852456"/>
            <joint name="panda_joint1" pos="0 0 0" axis="0 0 1" limited="true" range="-2.8973 2.8973" damping="1" frictionloss="0.1"/>
            <geom type="mesh" contype="0" conaffinity="0" group="1" mesh="panda visual link1"/>
            <geom type="mesh" mesh="panda collision link1"/>
            <body name="panda_link2" pos="0 0 0" quat="0.707107 -0.707107 0 0">
                <inertial pos="0 0 0" quat="-0.168175 0.828366 -0.122878 0.520027" mass="2.36" diaginertia="0.0310326 0.0283001 0.00273425"/>
                <joint name="panda_joint2" pos="0 0 0" axis="0 0 1" limited="true" range="-1.7628 1.7628" damping="1" frictionloss="0.1"/>
                <geom type="mesh" contype="0" conaffinity="0" group="1" mesh="panda visual link2"/>
                <geom type="mesh" mesh="panda collision link2"/>
                <body name="panda_link3" pos="0 -0.316 0" quat="0.707107 0.707107 0 0">
                    <inertial pos="0 0 0" quat="0.662769 -0.00678331 0.252053 0.705096" mass="2.38" diaginertia="0.0415014 0.0414793 0.00124635"/>
                    <joint name="panda_joint3" pos="0 0 0" axis="0 0 1" limited="true" range="-2.8973 2.8973" damping="1" frictionloss="0.1"/>
                    <geom type="mesh" contype="0" conaffinity="0" group="1" mesh="panda visual link3"/>
                    <geom type="mesh" mesh="panda collision link3"/>
                    <body name="panda_link4" pos="0.0825 0 0" quat="0.707107 0.707107 0 0">
                        <inertial pos="0 0 0" quat="0.65058 0.529822 -0.0962034 0.535518" mass="2.43" diaginertia="0.0349596 0.0281483 0.0106201"/>
                        <joint name="panda_joint4" pos="0 0 0" axis="0 0 1" limited="true" range="-3.0718 -0.0698" damping="1" frictionloss="0.1"/>
                        <geom type="mesh" contype="0" conaffinity="0" group="1" mesh="panda visual link4"/>
                        <geom type="mesh" mesh="panda collision link4"/>
                        <body name="panda_link5" pos="-0.0825 0.384 0" quat="0.707107 -0.707107 0 0">
                            <inertial pos="0 0 0" quat="0.987313 -0.0121954 0.0719187 -0.141037" mass="3.5" diaginertia="0.0367625 0.0288531 0.00803437"/>
                            <joint name="panda_joint5" pos="0 0 0" axis="0 0 1" limited="true" range="-2.8973 2.8973" damping="1" frictionloss="0.1"/>
                            <geom type="mesh" contype="0" conaffinity="0" group="1" mesh="panda visual link5"/>
                            <geom type="mesh" mesh="panda collision link5"/>
                            <body name="panda_link6" pos="0 0 0" quat="0.707107 0.707107 0 0">
                                <inertial pos="0 0 0" quat="0.101075 0.59332 0.0287227 0.798079" mass="1.47" diaginertia="0.00584276 0.00431037 0.00159787"/>
                                <joint name="panda_joint6" pos="0 0 0" axis="0 0 1" limited="true" range="-0.0175 3.7525" damping="1" frictionloss="0.1"/>
                                <geom type="mesh" contype="0" conaffinity="0" group="1" mesh="panda visual link6"/>
                                <geom type="mesh" mesh="panda collision link6"/>
                                <body name="panda_link7" pos="0.088 0 0" quat="0.707107 0.707107 0 0">
                                    <inertial pos="0 0 0.211538" quat="0.997616 -0.0102296 0.0136011 -0.0668798" mass="1.95" diaginertia="0.0487838 0.0461888 0.00990125"/>
                                    <joint name="panda_joint7" pos="0 0 0" axis="0 0 1" limited="true" range="-2.8973 2.8973" damping="1" frictionloss="0.1"/>
                                    <geom type="mesh" contype="0" conaffinity="0" group="1" mesh="panda visual link7"/>
                                    <geom type="mesh" mesh="panda collision link7"/>
                                    <geom pos="0 0 0.25" quat="0.92388 0 0 -0.382683" type="mesh" contype="0" conaffinity="0" group="1" mesh="main body visual"/>
                                    <geom size="0.03 0.05" pos="0 0 0.25" quat="0.92388 0 0 -0.382683" type="cylinder"/>
                                    <body name="finger_1_intermediate" pos="0 0 0.25" quat="0.653281 -0.270598 -0.653281 -0.270598">
                                        <inertial pos="0 0 0" quat="0.37634 0.403447 0.585982 0.593484" mass="0.1" diaginertia="0.000166494 0.00015418 3.54554e-05"/>
                                        <joint name="finger_1_prismatic_joint" pos="0 0 0" axis="0 1 0" type="slide" limited="true" range="0.053 0.141" damping="1"/>
                                        <geom type="mesh" contype="0" conaffinity="0" group="1" mesh="nut visual"/>
                                        <geom type="mesh" mesh="nut collision"/>
                                        <body name="finger_1" pos="0 0 0">
                                            <inertial pos="0.00768339 -0.000416928 0" quat="0.305036 0.562694 0.431992 0.635383" mass="0.106333" diaginertia="0.000255821 0.000253984 4.74922e-05"/>
                                            <joint name="finger_1_revolute_joint" pos="0 0 0" axis="0 0 1" limited="true" range="-0.7 0.7" damping="1"/>
                                            <geom type="mesh" contype="0" conaffinity="0" group="1" mesh="platform only visual"/>
                                            <geom type="mesh" mesh="platform only collision"/>
                                            <geom size="0.0095 0.014 0.00045" pos="0.1385 -0.007 0" quat="0.707107 0.707107 0 0" type="box" contype="0" conaffinity="0" group="1"/>
                                            <geom size="0.0095 0.014 0.00045" pos="0.1385 -0.007 0" quat="0.707107 0.707107 0 0" type="box"/>
                                            <body name="finger_1_segment_link_2" pos="0.148 -0.007 0" quat="0.707107 0.707107 0 0">
                                                <inertial pos="0 0 0" quat="0 0.707107 0 0.707107" mass="0.00633333" diaginertia="1.17589e-06 7.62539e-07 4.14205e-07"/>
                                                <joint name="finger_1_segment_joint_1" pos="0 0 0" axis="0 1 0" limited="true" range="-1 1" damping="0.01" stiffness="5"/>
                                                <geom size="0.0095 0.014 0.00045" pos="0.0095 0 0" type="box" contype="0" conaffinity="0" group="1"/>
                                                <geom size="0.0095 0.014 0.00045" pos="0.0095 0 0" type="box"/>
                                                <body name="finger_1_segment_link_3" pos="0.019 0 0">
                                                    <inertial pos="0 0 0" quat="0 0.707107 0 0.707107" mass="0.00633333" diaginertia="1.17589e-06 7.62539e-07 4.14205e-07"/>
                                                    <joint name="finger_1_segment_joint_2" pos="0 0 0" axis="0 1 0" limited="true" range="-1 1" damping="0.01" stiffness="5"/>
                                                    <geom size="0.0095 0.014 0.00045" pos="0.0095 0 0" type="box" contype="0" conaffinity="0" group="1"/>
                                                    <geom size="0.0095 0.014 0.00045" pos="0.0095 0 0" type="box"/>
                                                    <body name="finger_1_segment_link_4" pos="0.019 0 0">
                                                        <inertial pos="0 0 0" quat="0 0.707107 0 0.707107" mass="0.00633333" diaginertia="1.17589e-06 7.62539e-07 4.14205e-07"/>
                                                        <joint name="finger_1_segment_joint_3" pos="0 0 0" axis="0 1 0" limited="true" range="-1 1" damping="0.01" stiffness="5"/>
                                                        <geom size="0.0095 0.014 0.00045" pos="0.0095 0 0" type="box" contype="0" conaffinity="0" group="1"/>
                                                        <geom size="0.0095 0.014 0.00045" pos="0.0095 0 0" type="box"/>
                                                        <body name="finger_1_segment_link_5" pos="0.019 0 0">
                                                            <inertial pos="0 0 0" quat="0 0.707107 0 0.707107" mass="0.00633333" diaginertia="1.17589e-06 7.62539e-07 4.14205e-07"/>
                                                            <joint name="finger_1_segment_joint_4" pos="0 0 0" axis="0 1 0" limited="true" range="-1 1" damping="0.01" stiffness="5"/>
                                                            <geom size="0.0095 0.014 0.00045" pos="0.0095 0 0" type="box" contype="0" conaffinity="0" group="1"/>
                                                            <geom size="0.0095 0.014 0.00045" pos="0.0095 0 0" type="box"/>
                                                            <body name="finger_1_segment_link_6" pos="0.019 0 0">
                                                                <inertial pos="0 0 0" quat="0 0.707107 0 0.707107" mass="0.00633333" diaginertia="1.17589e-06 7.62539e-07 4.14205e-07"/>
                                                                <joint name="finger_1_segment_joint_5" pos="0 0 0" axis="0 1 0" limited="true" range="-1 1" damping="0.01" stiffness="5"/>
                                                                <geom size="0.0095 0.014 0.00045" pos="0.0095 0 0" type="box" contype="0" conaffinity="0" group="1"/>
                                                                <geom size="0.0095 0.014 0.00045" pos="0.0095 0 0" type="box"/>
                                                                <body name="finger_1_segment_link_7" pos="0.019 0 0">
                                                                    <inertial pos="0 0 0" quat="0 0.707107 0 0.707107" mass="0.00633333" diaginertia="1.17589e-06 7.62539e-07 4.14205e-07"/>
                                                                    <joint name="finger_1_segment_joint_6" pos="0 0 0" axis="0 1 0" limited="true" range="-1 1" damping="0.01" stiffness="5"/>
                                                                    <geom size="0.0095 0.014 0.00045" pos="0.0095 0 0" type="box" contype="0" conaffinity="0" group="1"/>
                                                                    <geom size="0.0095 0.014 0.00045" pos="0.0095 0 0" type="box"/>
                                                                    <body name="finger_1_segment_link_8" pos="0.019 0 0">
                                                                        <inertial pos="0 0 0" quat="0 0.707107 0 0.707107" mass="0.00633333" diaginertia="1.17589e-06 7.62539e-07 4.14205e-07"/>
                                                                        <joint name="finger_1_segment_joint_7" pos="0 0 0" axis="0 1 0" limited="true" range="-1 1" damping="0.01" stiffness="5"/>
                                                                        <geom size="0.0095 0.014 0.00045" pos="0.0095 0 0" type="box" contype="0" conaffinity="0" group="1"/>
                                                                        <geom size="0.0095 0.014 0.00045" pos="0.0095 0 0" type="box"/>
                                                                        <body name="finger_1_segment_link_9" pos="0.019 0 0">
                                                                            <inertial pos="0 0 0" quat="0 0.707107 0 0.707107" mass="0.00633333" diaginertia="1.17589e-06 7.62539e-07 4.14205e-07"/>
                                                                            <joint name="finger_1_segment_joint_8" pos="0 0 0" axis="0 1 0" limited="true" range="-1 1" damping="0.01" stiffness="5"/>
                                                                            <geom size="0.0095 0.014 0.00045" pos="0.0095 0 0" type="box" contype="0" conaffinity="0" group="1"/>
                                                                            <geom size="0.0095 0.014 0.00045" pos="0.0095 0 0" type="box"/>
                                                                            <body name="finger_1_segment_link_10" pos="0.019 0 0">
                                                                                <inertial pos="0.0095 0 0" quat="0 0.707107 0 0.707107" mass="0.0126667" diaginertia="2.73326e-06 2.66824e-06 1.59009e-06"/>
                                                                                <joint name="finger_1_segment_joint_9" pos="0 0 0" axis="0 1 0" limited="true" range="-1 1" damping="0.01" stiffness="5"/>
                                                                                <geom size="0.0095 0.014 0.00045" pos="0.0095 0 0" type="box" contype="0" conaffinity="0" group="1"/>
                                                                                <geom size="0.0095 0.014 0.00045" pos="0.0095 0 0" type="box"/>
                                                                                <geom size="0.0175 0.014 0.00045" pos="0.019 0 0.0175" quat="0.707107 0 -0.707107 0" type="box" contype="0" conaffinity="0" group="1"/>
                                                                                <geom size="0.0175 0.014 0.00045" pos="0.019 0 0.0175" quat="0.707107 0 -0.707107 0" type="box"/>
                                                                            </body>
                                                                        </body>
                                                                    </body>
                                                                </body>
                                                            </body>
                                                        </body>
                                                    </body>
                                                </body>
                                            </body>
                                        </body>
                                    </body>
                                    <body name="finger_2_intermediate" pos="0 0 0.25" quat="0.092296 -0.701057 -0.092296 -0.701057">
                                        <inertial pos="0 0 0" quat="0.37634 0.403447 0.585982 0.593484" mass="0.1" diaginertia="0.000166494 0.00015418 3.54554e-05"/>
                                        <joint name="finger_2_prismatic_joint" pos="0 0 0" axis="0 1 0" type="slide" limited="true" range="0.053 0.141" damping="1"/>
                                        <geom type="mesh" contype="0" conaffinity="0" group="1" mesh="nut visual"/>
                                        <geom type="mesh" mesh="nut collision"/>
                                        <body name="finger_2" pos="0 0 0">
                                            <inertial pos="0.00768339 -0.000416928 0" quat="0.305036 0.562694 0.431992 0.635383" mass="0.106333" diaginertia="0.000255821 0.000253984 4.74922e-05"/>
                                            <joint name="finger_2_revolute_joint" pos="0 0 0" axis="0 0 1" limited="true" range="-0.7 0.7" damping="1"/>
                                            <geom type="mesh" contype="0" conaffinity="0" group="1" mesh="platform only visual"/>
                                            <geom type="mesh" mesh="platform only collision"/>
                                            <geom size="0.0095 0.014 0.00045" pos="0.1385 -0.007 0" quat="0.707107 0.707107 0 0" type="box" contype="0" conaffinity="0" group="1"/>
                                            <geom size="0.0095 0.014 0.00045" pos="0.1385 -0.007 0" quat="0.707107 0.707107 0 0" type="box"/>
                                            <body name="finger_2_segment_link_2" pos="0.148 -0.007 0" quat="0.707107 0.707107 0 0">
                                                <inertial pos="0 0 0" quat="0 0.707107 0 0.707107" mass="0.00633333" diaginertia="1.17589e-06 7.62539e-07 4.14205e-07"/>
                                                <joint name="finger_2_segment_joint_1" pos="0 0 0" axis="0 1 0" limited="true" range="-1 1" damping="0.01" stiffness="5"/>
                                                <geom size="0.0095 0.014 0.00045" pos="0.0095 0 0" type="box" contype="0" conaffinity="0" group="1"/>
                                                <geom size="0.0095 0.014 0.00045" pos="0.0095 0 0" type="box"/>
                                                <body name="finger_2_segment_link_3" pos="0.019 0 0">
                                                    <inertial pos="0 0 0" quat="0 0.707107 0 0.707107" mass="0.00633333" diaginertia="1.17589e-06 7.62539e-07 4.14205e-07"/>
                                                    <joint name="finger_2_segment_joint_2" pos="0 0 0" axis="0 1 0" limited="true" range="-1 1" damping="0.01" stiffness="5"/>
                                                    <geom size="0.0095 0.014 0.00045" pos="0.0095 0 0" type="box" contype="0" conaffinity="0" group="1"/>
                                                    <geom size="0.0095 0.014 0.00045" pos="0.0095 0 0" type="box"/>
                                                    <body name="finger_2_segment_link_4" pos="0.019 0 0">
                                                        <inertial pos="0 0 0" quat="0 0.707107 0 0.707107" mass="0.00633333" diaginertia="1.17589e-06 7.62539e-07 4.14205e-07"/>
                                                        <joint name="finger_2_segment_joint_3" pos="0 0 0" axis="0 1 0" limited="true" range="-1 1" damping="0.01" stiffness="5"/>
                                                        <geom size="0.0095 0.014 0.00045" pos="0.0095 0 0" type="box" contype="0" conaffinity="0" group="1"/>
                                                        <geom size="0.0095 0.014 0.00045" pos="0.0095 0 0" type="box"/>
                                                        <body name="finger_2_segment_link_5" pos="0.019 0 0">
                                                            <inertial pos="0 0 0" quat="0 0.707107 0 0.707107" mass="0.00633333" diaginertia="1.17589e-06 7.62539e-07 4.14205e-07"/>
                                                            <joint name="finger_2_segment_joint_4" pos="0 0 0" axis="0 1 0" limited="true" range="-1 1" damping="0.01" stiffness="5"/>
                                                            <geom size="0.0095 0.014 0.00045" pos="0.0095 0 0" type="box" contype="0" conaffinity="0" group="1"/>
                                                            <geom size="0.0095 0.014 0.00045" pos="0.0095 0 0" type="box"/>
                                                            <body name="finger_2_segment_link_6" pos="0.019 0 0">
                                                                <inertial pos="0 0 0" quat="0 0.707107 0 0.707107" mass="0.00633333" diaginertia="1.17589e-06 7.62539e-07 4.14205e-07"/>
                                                                <joint name="finger_2_segment_joint_5" pos="0 0 0" axis="0 1 0" limited="true" range="-1 1" damping="0.01" stiffness="5"/>
                                                                <geom size="0.0095 0.014 0.00045" pos="0.0095 0 0" type="box" contype="0" conaffinity="0" group="1"/>
                                                                <geom size="0.0095 0.014 0.00045" pos="0.0095 0 0" type="box"/>
                                                                <body name="finger_2_segment_link_7" pos="0.019 0 0">
                                                                    <inertial pos="0 0 0" quat="0 0.707107 0 0.707107" mass="0.00633333" diaginertia="1.17589e-06 7.62539e-07 4.14205e-07"/>
                                                                    <joint name="finger_2_segment_joint_6" pos="0 0 0" axis="0 1 0" limited="true" range="-1 1" damping="0.01" stiffness="5"/>
                                                                    <geom size="0.0095 0.014 0.00045" pos="0.0095 0 0" type="box" contype="0" conaffinity="0" group="1"/>
                                                                    <geom size="0.0095 0.014 0.00045" pos="0.0095 0 0" type="box"/>
                                                                    <body name="finger_2_segment_link_8" pos="0.019 0 0">
                                                                        <inertial pos="0 0 0" quat="0 0.707107 0 0.707107" mass="0.00633333" diaginertia="1.17589e-06 7.62539e-07 4.14205e-07"/>
                                                                        <joint name="finger_2_segment_joint_7" pos="0 0 0" axis="0 1 0" limited="true" range="-1 1" damping="0.01" stiffness="5"/>
                                                                        <geom size="0.0095 0.014 0.00045" pos="0.0095 0 0" type="box" contype="0" conaffinity="0" group="1"/>
                                                                        <geom size="0.0095 0.014 0.00045" pos="0.0095 0 0" type="box"/>
                                                                        <body name="finger_2_segment_link_9" pos="0.019 0 0">
                                                                            <inertial pos="0 0 0" quat="0 0.707107 0 0.707107" mass="0.00633333" diaginertia="1.17589e-06 7.62539e-07 4.14205e-07"/>
                                                                            <joint name="finger_2_segment_joint_8" pos="0 0 0" axis="0 1 0" limited="true" range="-1 1" damping="0.01" stiffness="5"/>
                                                                            <geom size="0.0095 0.014 0.00045" pos="0.0095 0 0" type="box" contype="0" conaffinity="0" group="1"/>
                                                                            <geom size="0.0095 0.014 0.00045" pos="0.0095 0 0" type="box"/>
                                                                            <body name="finger_2_segment_link_10" pos="0.019 0 0">
                                                                                <inertial pos="0.0095 0 0" quat="0 0.707107 0 0.707107" mass="0.0126667" diaginertia="2.73326e-06 2.66824e-06 1.59009e-06"/>
                                                                                <joint name="finger_2_segment_joint_9" pos="0 0 0" axis="0 1 0" limited="true" range="-1 1" damping="0.01" stiffness="5"/>
                                                                                <geom size="0.0095 0.014 0.00045" pos="0.0095 0 0" type="box" contype="0" conaffinity="0" group="1"/>
                                                                                <geom size="0.0095 0.014 0.00045" pos="0.0095 0 0" type="box"/>
                                                                                <geom size="0.0175 0.014 0.00045" pos="0.019 0 0.0175" quat="0.707107 0 -0.707107 0" type="box" contype="0" conaffinity="0" group="1"/>
                                                                                <geom size="0.0175 0.014 0.00045" pos="0.019 0 0.0175" quat="0.707107 0 -0.707107 0" type="box"/>
                                                                            </body>
                                                                        </body>
                                                                    </body>
                                                                </body>
                                                            </body>
                                                        </body>
                                                    </body>
                                                </body>
                                            </body>
                                        </body>
                                    </body>
                                    <body name="finger_3_intermediate" pos="0 0 0.25" quat="-0.560986 -0.430459 0.560986 -0.430459">
                                        <inertial pos="0 0 0" quat="0.37634 0.403447 0.585982 0.593484" mass="0.1" diaginertia="0.000166494 0.00015418 3.54554e-05"/>
                                        <joint name="finger_3_prismatic_joint" pos="0 0 0" axis="0 1 0" type="slide" limited="true" range="0.053 0.141" damping="1"/>
                                        <geom type="mesh" contype="0" conaffinity="0" group="1" mesh="nut visual"/>
                                        <geom type="mesh" mesh="nut collision"/>
                                        <body name="finger_3" pos="0 0 0">
                                            <inertial pos="0.00768339 -0.000416928 0" quat="0.305036 0.562694 0.431992 0.635383" mass="0.106333" diaginertia="0.000255821 0.000253984 4.74922e-05"/>
                                            <joint name="finger_3_revolute_joint" pos="0 0 0" axis="0 0 1" limited="true" range="-0.7 0.7" damping="1"/>
                                            <geom type="mesh" contype="0" conaffinity="0" group="1" mesh="platform only visual"/>
                                            <geom type="mesh" mesh="platform only collision"/>
                                            <geom size="0.0095 0.014 0.00045" pos="0.1385 -0.007 0" quat="0.707107 0.707107 0 0" type="box" contype="0" conaffinity="0" group="1"/>
                                            <geom size="0.0095 0.014 0.00045" pos="0.1385 -0.007 0" quat="0.707107 0.707107 0 0" type="box"/>
                                            <body name="finger_3_segment_link_2" pos="0.148 -0.007 0" quat="0.707107 0.707107 0 0">
                                                <inertial pos="0 0 0" quat="0 0.707107 0 0.707107" mass="0.00633333" diaginertia="1.17589e-06 7.62539e-07 4.14205e-07"/>
                                                <joint name="finger_3_segment_joint_1" pos="0 0 0" axis="0 1 0" limited="true" range="-1 1" damping="0.01" stiffness="5"/>
                                                <geom size="0.0095 0.014 0.00045" pos="0.0095 0 0" type="box" contype="0" conaffinity="0" group="1"/>
                                                <geom size="0.0095 0.014 0.00045" pos="0.0095 0 0" type="box"/>
                                                <body name="finger_3_segment_link_3" pos="0.019 0 0">
                                                    <inertial pos="0 0 0" quat="0 0.707107 0 0.707107" mass="0.00633333" diaginertia="1.17589e-06 7.62539e-07 4.14205e-07"/>
                                                    <joint name="finger_3_segment_joint_2" pos="0 0 0" axis="0 1 0" limited="true" range="-1 1" damping="0.01" stiffness="5"/>
                                                    <geom size="0.0095 0.014 0.00045" pos="0.0095 0 0" type="box" contype="0" conaffinity="0" group="1"/>
                                                    <geom size="0.0095 0.014 0.00045" pos="0.0095 0 0" type="box"/>
                                                    <body name="finger_3_segment_link_4" pos="0.019 0 0">
                                                        <inertial pos="0 0 0" quat="0 0.707107 0 0.707107" mass="0.00633333" diaginertia="1.17589e-06 7.62539e-07 4.14205e-07"/>
                                                        <joint name="finger_3_segment_joint_3" pos="0 0 0" axis="0 1 0" limited="true" range="-1 1" damping="0.01" stiffness="5"/>
                                                        <geom size="0.0095 0.014 0.00045" pos="0.0095 0 0" type="box" contype="0" conaffinity="0" group="1"/>
                                                        <geom size="0.0095 0.014 0.00045" pos="0.0095 0 0" type="box"/>
                                                        <body name="finger_3_segment_link_5" pos="0.019 0 0">
                                                            <inertial pos="0 0 0" quat="0 0.707107 0 0.707107" mass="0.00633333" diaginertia="1.17589e-06 7.62539e-07 4.14205e-07"/>
                                                            <joint name="finger_3_segment_joint_4" pos="0 0 0" axis="0 1 0" limited="true" range="-1 1" damping="0.01" stiffness="5"/>
                                                            <geom size="0.0095 0.014 0.00045" pos="0.0095 0 0" type="box" contype="0" conaffinity="0" group="1"/>
                                                            <geom size="0.0095 0.014 0.00045" pos="0.0095 0 0" type="box"/>
                                                            <body name="finger_3_segment_link_6" pos="0.019 0 0">
                                                                <inertial pos="0 0 0" quat="0 0.707107 0 0.707107" mass="0.00633333" diaginertia="1.17589e-06 7.62539e-07 4.14205e-07"/>
                                                                <joint name="finger_3_segment_joint_5" pos="0 0 0" axis="0 1 0" limited="true" range="-1 1" damping="0.01" stiffness="5"/>
                                                                <geom size="0.0095 0.014 0.00045" pos="0.0095 0 0" type="box" contype="0" conaffinity="0" group="1"/>
                                                                <geom size="0.0095 0.014 0.00045" pos="0.0095 0 0" type="box"/>
                                                                <body name="finger_3_segment_link_7" pos="0.019 0 0">
                                                                    <inertial pos="0 0 0" quat="0 0.707107 0 0.707107" mass="0.00633333" diaginertia="1.17589e-06 7.62539e-07 4.14205e-07"/>
                                                                    <joint name="finger_3_segment_joint_6" pos="0 0 0" axis="0 1 0" limited="true" range="-1 1" damping="0.01" stiffness="5"/>
                                                                    <geom size="0.0095 0.014 0.00045" pos="0.0095 0 0" type="box" contype="0" conaffinity="0" group="1"/>
                                                                    <geom size="0.0095 0.014 0.00045" pos="0.0095 0 0" type="box"/>
                                                                    <body name="finger_3_segment_link_8" pos="0.019 0 0">
                                                                        <inertial pos="0 0 0" quat="0 0.707107 0 0.707107" mass="0.00633333" diaginertia="1.17589e-06 7.62539e-07 4.14205e-07"/>
                                                                        <joint name="finger_3_segment_joint_7" pos="0 0 0" axis="0 1 0" limited="true" range="-1 1" damping="0.01" stiffness="5"/>
                                                                        <geom size="0.0095 0.014 0.00045" pos="0.0095 0 0" type="box" contype="0" conaffinity="0" group="1"/>
                                                                        <geom size="0.0095 0.014 0.00045" pos="0.0095 0 0" type="box"/>
                                                                        <body name="finger_3_segment_link_9" pos="0.019 0 0">
                                                                            <inertial pos="0 0 0" quat="0 0.707107 0 0.707107" mass="0.00633333" diaginertia="1.17589e-06 7.62539e-07 4.14205e-07"/>
                                                                            <joint name="finger_3_segment_joint_8" pos="0 0 0" axis="0 1 0" limited="true" range="-1 1" damping="0.01" stiffness="5"/>
                                                                            <geom size="0.0095 0.014 0.00045" pos="0.0095 0 0" type="box" contype="0" conaffinity="0" group="1"/>
                                                                            <geom size="0.0095 0.014 0.00045" pos="0.0095 0 0" type="box"/>
                                                                            <body name="finger_3_segment_link_10" pos="0.019 0 0">
                                                                                <inertial pos="0.0095 0 0" quat="0 0.707107 0 0.707107" mass="0.0126667" diaginertia="2.73326e-06 2.66824e-06 1.59009e-06"/>
                                                                                <joint name="finger_3_segment_joint_9" pos="0 0 0" axis="0 1 0" limited="true" range="-1 1" damping="0.01" stiffness="5"/>
                                                                                <geom size="0.0095 0.014 0.00045" pos="0.0095 0 0" type="box" contype="0" conaffinity="0" group="1"/>
                                                                                <geom size="0.0095 0.014 0.00045" pos="0.0095 0 0" type="box"/>
                                                                                <geom size="0.0175 0.014 0.00045" pos="0.019 0 0.0175" quat="0.707107 0 -0.707107 0" type="box" contype="0" conaffinity="0" group="1"/>
                                                                                <geom size="0.0175 0.014 0.00045" pos="0.019 0 0.0175" quat="0.707107 0 -0.707107 0" type="box"/>
                                                                            </body>
                                                                        </body>
                                                                    </body>
                                                                </body>
                                                            </body>
                                                        </body>
                                                    </body>
                                                </body>
                                            </body>
                                        </body>
                                    </body>
                                    <body name="palm" pos="0 0 0.25" quat="0.653281 -0.270598 -0.653281 -0.270598">
                                        <inertial pos="0 0 0" mass="0.05" diaginertia="1e-05 1e-05 1e-05"/>
                                        <joint name="palm_prismatic_joint" pos="0 0 0" axis="1 0 0" type="slide" limited="true" range="0 0.16" damping="1"/>
                                        <geom type="mesh" contype="0" conaffinity="0" group="1" mesh="palm visual"/>
                                        <geom type="mesh" mesh="palm collision"/>
                                    </body>
                                </body>
                            </body>
                        </body>
                    </body>
                </body>
            </body>
        </body>
    </worldbody>
<keyframe>
    <key name="initial pose" time="0" qpos="0.01 0.02 0.03 0.04 0.05 1.0 0.07 0.14 0.0 0 0 0 0 0 0 0 0 0  0.14 0.0 0 0 0 0 0 0 0 0 0  0.14 0.0 0 0 0 0 0 0 0 0 0  0.0"/>
  </keyframe><actuator>
    
  <motor name="panda_joint1_actuator" joint="panda_joint1"/>

  <motor name="panda_joint2_actuator" joint="panda_joint2"/>

  <motor name="panda_joint3_actuator" joint="panda_joint3"/>

  <motor name="panda_joint4_actuator" joint="panda_joint4"/>

  <motor name="panda_joint5_actuator" joint="panda_joint5"/>

  <motor name="panda_joint6_actuator" joint="panda_joint6"/>

  <motor name="panda_joint7_actuator" joint="panda_joint7"/>

    
  <motor name="finger_1_prismatic_joint_actuator" joint="finger_1_prismatic_joint"/>

  <motor name="finger_1_revolute_joint_actuator" joint="finger_1_revolute_joint"/>

  <motor name="finger_2_prismatic_joint_actuator" joint="finger_2_prismatic_joint"/>

  <motor name="finger_2_revolute_joint_actuator" joint="finger_2_revolute_joint"/>

  <motor name="finger_3_prismatic_joint_actuator" joint="finger_3_prismatic_joint"/>

  <motor name="finger_3_revolute_joint_actuator" joint="finger_3_revolute_joint"/>

  <motor name="palm_prismatic_joint_actuator" joint="palm_prismatic_joint"/>

    
  <motor name="finger_1_segment_joint_1_actuator" joint="finger_1_segment_joint_1"/>

  <motor name="finger_1_segment_joint_2_actuator" joint="finger_1_segment_joint_2"/>

  <motor name="finger_1_segment_joint_3_actuator" joint="finger_1_segment_joint_3"/>

  <motor name="finger_1_segment_joint_4_actuator" joint="finger_1_segment_joint_4"/>

  <motor name="finger_1_segment_joint_5_actuator" joint="finger_1_segment_joint_5"/>

  <motor name="finger_1_segment_joint_6_actuator" joint="finger_1_segment_joint_6"/>

  <motor name="finger_1_segment_joint_7_actuator" joint="finger_1_segment_joint_7"/>

  <motor name="finger_1_segment_joint_8_actuator" joint="finger_1_segment_joint_8"/>

  <motor name="finger_1_segment_joint_9_actuator" joint="finger_1_segment_joint_9"/>

  <motor name="finger_2_segment_joint_1_actuator" joint="finger_2_segment_joint_1"/>

  <motor name="finger_2_segment_joint_2_actuator" joint="finger_2_segment_joint_2"/>

  <motor name="finger_2_segment_joint_3_actuator" joint="finger_2_segment_joint_3"/>

  <motor name="finger_2_segment_joint_4_actuator" joint="finger_2_segment_joint_4"/>

  <motor name="finger_2_segment_joint_5_actuator" joint="finger_2_segment_joint_5"/>

  <motor name="finger_2_segment_joint_6_actuator" joint="finger_2_segment_joint_6"/>

  <motor name="finger_2_segment_joint_7_actuator" joint="finger_2_segment_joint_7"/>

  <motor name="finger_2_segment_joint_8_actuator" joint="finger_2_segment_joint_8"/>

  <motor name="finger_2_segment_joint_9_actuator" joint="finger_2_segment_joint_9"/>

  <motor name="finger_3_segment_joint_1_actuator" joint="finger_3_segment_joint_1"/>

  <motor name="finger_3_segment_joint_2_actuator" joint="finger_3_segment_joint_2"/>

  <motor name="finger_3_segment_joint_3_actuator" joint="finger_3_segment_joint_3"/>

  <motor name="finger_3_segment_joint_4_actuator" joint="finger_3_segment_joint_4"/>

  <motor name="finger_3_segment_joint_5_actuator" joint="finger_3_segment_joint_5"/>

  <motor name="finger_3_segment_joint_6_actuator" joint="finger_3_segment_joint_6"/>

  <motor name="finger_3_segment_joint_7_actuator" joint="finger_3_segment_joint_7"/>

  <motor name="finger_3_segment_joint_8_actuator" joint="finger_3_segment_joint_8"/>

  <motor name="finger_3_segment_joint_9_actuator" joint="finger_3_segment_joint_9"/>

  </actuator></mujoco>