<mujoco model="gripper_task">
    <compiler angle="radian" meshdir="../meshes_mujoco"/>
    <size njmax="1400" nconmax="500"/>
    <asset>
        <mesh name="main body visual" file="main body visual.STL"/>
        <mesh name="nut visual" file="nut visual.STL"/>
        <mesh name="nut collision" file="nut collision.STL"/>
        <mesh name="platform only visual" file="platform only visual.STL"/>
        <mesh name="platform only collision" file="platform only collision.STL"/>
        <mesh name="palm visual" file="palm visual.STL"/>
        <mesh name="palm collision" file="palm collision.STL"/>
    <include file="../mjcf_include/assets/assets_35.xml"/></asset>
    <worldbody>
        <body name="gripper_base_link" pos="0 0 0.335" quat="0 1 0 0">
            <inertial pos="0 0 0.025" quat="-0.00978477 0.713334 -0.700715 -0.00752147" mass="1.5" diaginertia="0.010083 0.00995 0.00512698"/>
            <joint name="world_to_base" pos="0 0 0" axis="0 0 1" type="slide" limited="true" range="-1 1" damping="1"/>
            <geom type="mesh" contype="0" conaffinity="0" group="1" mesh="main body visual"/>
            <geom size="0.03 0.05" type="cylinder"/>
            <body name="finger_1_intermediate" pos="0 0 0" quat="0.707107 -1.73123e-12 -0.707107 -5.0473e-12">
                <inertial pos="0 0 0" quat="0.37634 0.403447 0.585982 0.593484" mass="0.1" diaginertia="0.000166494 0.00015418 3.54554e-05"/>
                <joint name="finger_1_prismatic_joint" pos="0 0 0" axis="0 1 0" type="slide" limited="true" range="0.053 0.141" damping="1"/>
                <geom type="mesh" contype="0" conaffinity="0" group="1" mesh="nut visual"/>
                <geom type="mesh" mesh="nut collision"/>
                <body name="finger_1" pos="0 0 0">
                    <inertial pos="0.00768339 -0.000416928 0" quat="0.305036 0.562694 0.431992 0.635383" mass="0.106333" diaginertia="0.000255821 0.000253984 4.74922e-05"/>
                    <joint name="finger_1_revolute_joint" pos="0 0 0" axis="0 0 1" limited="true" range="-0.7 0.7" damping="1"/>
                    <geom type="mesh" contype="0" conaffinity="0" group="1" mesh="platform only visual"/>
                    <geom type="mesh" mesh="platform only collision"/>
                    <geom size="0.0095 0.014 0.00045" pos="0.1385 -0.007 0" quat="0.707107 0.707107 0 0" type="box" contype="0" conaffinity="0" group="1"/>
                    <geom size="0.0095 0.014 0.00045" pos="0.1385 -0.007 0" quat="0.707107 0.707107 0 0" type="box"/>
                    <body name="finger_1_segment_link_2" pos="0.148 -0.007 0" quat="0.707107 0.707107 0 0">
                        <inertial pos="0 0 0" quat="0 0.707107 0 0.707107" mass="0.00633333" diaginertia="1.17589e-06 7.62539e-07 4.14205e-07"/>
                        <joint name="finger_1_segment_joint_1" pos="0 0 0" axis="0 1 0" limited="true" range="-1 1" damping="0.01" stiffness="5"/>
                        <geom size="0.0095 0.014 0.00045" pos="0.0095 0 0" type="box" contype="0" conaffinity="0" group="1" name="finger_1_segment_link_2_geom_visual"/>
                        <geom size="0.0095 0.014 0.00045" pos="0.0095 0 0" type="box" name="finger_1_segment_link_2_geom_collision"/>
                        <body name="finger_1_segment_link_3" pos="0.019 0 0">
                            <inertial pos="0 0 0" quat="0 0.707107 0 0.707107" mass="0.00633333" diaginertia="1.17589e-06 7.62539e-07 4.14205e-07"/>
                            <joint name="finger_1_segment_joint_2" pos="0 0 0" axis="0 1 0" limited="true" range="-1 1" damping="0.01" stiffness="5"/>
                            <geom size="0.0095 0.014 0.00045" pos="0.0095 0 0" type="box" contype="0" conaffinity="0" group="1" name="finger_1_segment_link_3_geom_visual"/>
                            <geom size="0.0095 0.014 0.00045" pos="0.0095 0 0" type="box" name="finger_1_segment_link_3_geom_collision"/>
                            <body name="finger_1_segment_link_4" pos="0.019 0 0">
                                <inertial pos="0 0 0" quat="0 0.707107 0 0.707107" mass="0.00633333" diaginertia="1.17589e-06 7.62539e-07 4.14205e-07"/>
                                <joint name="finger_1_segment_joint_3" pos="0 0 0" axis="0 1 0" limited="true" range="-1 1" damping="0.01" stiffness="5"/>
                                <geom size="0.0095 0.014 0.00045" pos="0.0095 0 0" type="box" contype="0" conaffinity="0" group="1" name="finger_1_segment_link_4_geom_visual"/>
                                <geom size="0.0095 0.014 0.00045" pos="0.0095 0 0" type="box" name="finger_1_segment_link_4_geom_collision"/>
                                <body name="finger_1_segment_link_5" pos="0.019 0 0">
                                    <inertial pos="0 0 0" quat="0 0.707107 0 0.707107" mass="0.00633333" diaginertia="1.17589e-06 7.62539e-07 4.14205e-07"/>
                                    <joint name="finger_1_segment_joint_4" pos="0 0 0" axis="0 1 0" limited="true" range="-1 1" damping="0.01" stiffness="5"/>
                                    <geom size="0.0095 0.014 0.00045" pos="0.0095 0 0" type="box" contype="0" conaffinity="0" group="1" name="finger_1_segment_link_5_geom_visual"/>
                                    <geom size="0.0095 0.014 0.00045" pos="0.0095 0 0" type="box" name="finger_1_segment_link_5_geom_collision"/>
                                    <body name="finger_1_segment_link_6" pos="0.019 0 0">
                                        <inertial pos="0 0 0" quat="0 0.707107 0 0.707107" mass="0.00633333" diaginertia="1.17589e-06 7.62539e-07 4.14205e-07"/>
                                        <joint name="finger_1_segment_joint_5" pos="0 0 0" axis="0 1 0" limited="true" range="-1 1" damping="0.01" stiffness="5"/>
                                        <geom size="0.0095 0.014 0.00045" pos="0.0095 0 0" type="box" contype="0" conaffinity="0" group="1" name="finger_1_segment_link_6_geom_visual"/>
                                        <geom size="0.0095 0.014 0.00045" pos="0.0095 0 0" type="box" name="finger_1_segment_link_6_geom_collision"/>
                                        <body name="finger_1_segment_link_7" pos="0.019 0 0">
                                            <inertial pos="0 0 0" quat="0 0.707107 0 0.707107" mass="0.00633333" diaginertia="1.17589e-06 7.62539e-07 4.14205e-07"/>
                                            <joint name="finger_1_segment_joint_6" pos="0 0 0" axis="0 1 0" limited="true" range="-1 1" damping="0.01" stiffness="5"/>
                                            <geom size="0.0095 0.014 0.00045" pos="0.0095 0 0" type="box" contype="0" conaffinity="0" group="1" name="finger_1_segment_link_7_geom_visual"/>
                                            <geom size="0.0095 0.014 0.00045" pos="0.0095 0 0" type="box" name="finger_1_segment_link_7_geom_collision"/>
                                            <body name="finger_1_segment_link_8" pos="0.019 0 0">
                                                <inertial pos="0 0 0" quat="0 0.707107 0 0.707107" mass="0.00633333" diaginertia="1.17589e-06 7.62539e-07 4.14205e-07"/>
                                                <joint name="finger_1_segment_joint_7" pos="0 0 0" axis="0 1 0" limited="true" range="-1 1" damping="0.01" stiffness="5"/>
                                                <geom size="0.0095 0.014 0.00045" pos="0.0095 0 0" type="box" contype="0" conaffinity="0" group="1" name="finger_1_segment_link_8_geom_visual"/>
                                                <geom size="0.0095 0.014 0.00045" pos="0.0095 0 0" type="box" name="finger_1_segment_link_8_geom_collision"/>
                                                <body name="finger_1_segment_link_9" pos="0.019 0 0">
                                                    <inertial pos="0 0 0" quat="0 0.707107 0 0.707107" mass="0.00633333" diaginertia="1.17589e-06 7.62539e-07 4.14205e-07"/>
                                                    <joint name="finger_1_segment_joint_8" pos="0 0 0" axis="0 1 0" limited="true" range="-1 1" damping="0.01" stiffness="5"/>
                                                    <geom size="0.0095 0.014 0.00045" pos="0.0095 0 0" type="box" contype="0" conaffinity="0" group="1" name="finger_1_segment_link_9_geom_visual"/>
                                                    <geom size="0.0095 0.014 0.00045" pos="0.0095 0 0" type="box" name="finger_1_segment_link_9_geom_collision"/>
                                                    <body name="finger_1_segment_link_10" pos="0.019 0 0">
                                                        <inertial pos="0.0095 0 0" quat="0 0.707107 0 0.707107" mass="0.0126667" diaginertia="2.73326e-06 2.66824e-06 1.59009e-06"/>
                                                        <joint name="finger_1_segment_joint_9" pos="0 0 0" axis="0 1 0" limited="true" range="-1 1" damping="0.01" stiffness="5"/>
                                                        <geom size="0.0095 0.014 0.00045" pos="0.0095 0 0" type="box" contype="0" conaffinity="0" group="1" name="finger_1_segment_link_10_geom_visual"/>
                                                        <geom size="0.0095 0.014 0.00045" pos="0.0095 0 0" type="box" name="finger_1_segment_link_10_geom_collision"/>
                                                        <geom size="0.0175 0.014 0.00045" pos="0.019 0 0.0175" quat="0.707107 0 -0.707107 0" type="box" contype="0" conaffinity="0" group="1" name="finger_1_segment_link_10_geom_hook_visual"/>
                                                        <geom size="0.0175 0.014 0.00045" pos="0.019 0 0.0175" quat="0.707107 0 -0.707107 0" type="box" name="finger_1_segment_link_10_geom_hook_collision"/>
                                                    </body>
                                                </body>
                                            </body>
                                        </body>
                                    </body>
                                </body>
                            </body>
                        </body>
                    </body>
                </body>
            </body>
            <body name="finger_2_intermediate" pos="0 0 0" quat="0.353553 -0.612372 -0.353553 -0.612372">
                <inertial pos="0 0 0" quat="0.37634 0.403447 0.585982 0.593484" mass="0.1" diaginertia="0.000166494 0.00015418 3.54554e-05"/>
                <joint name="finger_2_prismatic_joint" pos="0 0 0" axis="0 1 0" type="slide" limited="true" range="0.053 0.141" damping="1"/>
                <geom type="mesh" contype="0" conaffinity="0" group="1" mesh="nut visual"/>
                <geom type="mesh" mesh="nut collision"/>
                <body name="finger_2" pos="0 0 0">
                    <inertial pos="0.00768339 -0.000416928 0" quat="0.305036 0.562694 0.431992 0.635383" mass="0.106333" diaginertia="0.000255821 0.000253984 4.74922e-05"/>
                    <joint name="finger_2_revolute_joint" pos="0 0 0" axis="0 0 1" limited="true" range="-0.7 0.7" damping="1"/>
                    <geom type="mesh" contype="0" conaffinity="0" group="1" mesh="platform only visual"/>
                    <geom type="mesh" mesh="platform only collision"/>
                    <geom size="0.0095 0.014 0.00045" pos="0.1385 -0.007 0" quat="0.707107 0.707107 0 0" type="box" contype="0" conaffinity="0" group="1"/>
                    <geom size="0.0095 0.014 0.00045" pos="0.1385 -0.007 0" quat="0.707107 0.707107 0 0" type="box"/>
                    <body name="finger_2_segment_link_2" pos="0.148 -0.007 0" quat="0.707107 0.707107 0 0">
                        <inertial pos="0 0 0" quat="0 0.707107 0 0.707107" mass="0.00633333" diaginertia="1.17589e-06 7.62539e-07 4.14205e-07"/>
                        <joint name="finger_2_segment_joint_1" pos="0 0 0" axis="0 1 0" limited="true" range="-1 1" damping="0.01" stiffness="5"/>
                        <geom size="0.0095 0.014 0.00045" pos="0.0095 0 0" type="box" contype="0" conaffinity="0" group="1" name="finger_2_segment_link_2_geom_visual"/>
                        <geom size="0.0095 0.014 0.00045" pos="0.0095 0 0" type="box" name="finger_2_segment_link_2_geom_collision"/>
                        <body name="finger_2_segment_link_3" pos="0.019 0 0">
                            <inertial pos="0 0 0" quat="0 0.707107 0 0.707107" mass="0.00633333" diaginertia="1.17589e-06 7.62539e-07 4.14205e-07"/>
                            <joint name="finger_2_segment_joint_2" pos="0 0 0" axis="0 1 0" limited="true" range="-1 1" damping="0.01" stiffness="5"/>
                            <geom size="0.0095 0.014 0.00045" pos="0.0095 0 0" type="box" contype="0" conaffinity="0" group="1" name="finger_2_segment_link_3_geom_visual"/>
                            <geom size="0.0095 0.014 0.00045" pos="0.0095 0 0" type="box" name="finger_2_segment_link_3_geom_collision"/>
                            <body name="finger_2_segment_link_4" pos="0.019 0 0">
                                <inertial pos="0 0 0" quat="0 0.707107 0 0.707107" mass="0.00633333" diaginertia="1.17589e-06 7.62539e-07 4.14205e-07"/>
                                <joint name="finger_2_segment_joint_3" pos="0 0 0" axis="0 1 0" limited="true" range="-1 1" damping="0.01" stiffness="5"/>
                                <geom size="0.0095 0.014 0.00045" pos="0.0095 0 0" type="box" contype="0" conaffinity="0" group="1" name="finger_2_segment_link_4_geom_visual"/>
                                <geom size="0.0095 0.014 0.00045" pos="0.0095 0 0" type="box" name="finger_2_segment_link_4_geom_collision"/>
                                <body name="finger_2_segment_link_5" pos="0.019 0 0">
                                    <inertial pos="0 0 0" quat="0 0.707107 0 0.707107" mass="0.00633333" diaginertia="1.17589e-06 7.62539e-07 4.14205e-07"/>
                                    <joint name="finger_2_segment_joint_4" pos="0 0 0" axis="0 1 0" limited="true" range="-1 1" damping="0.01" stiffness="5"/>
                                    <geom size="0.0095 0.014 0.00045" pos="0.0095 0 0" type="box" contype="0" conaffinity="0" group="1" name="finger_2_segment_link_5_geom_visual"/>
                                    <geom size="0.0095 0.014 0.00045" pos="0.0095 0 0" type="box" name="finger_2_segment_link_5_geom_collision"/>
                                    <body name="finger_2_segment_link_6" pos="0.019 0 0">
                                        <inertial pos="0 0 0" quat="0 0.707107 0 0.707107" mass="0.00633333" diaginertia="1.17589e-06 7.62539e-07 4.14205e-07"/>
                                        <joint name="finger_2_segment_joint_5" pos="0 0 0" axis="0 1 0" limited="true" range="-1 1" damping="0.01" stiffness="5"/>
                                        <geom size="0.0095 0.014 0.00045" pos="0.0095 0 0" type="box" contype="0" conaffinity="0" group="1" name="finger_2_segment_link_6_geom_visual"/>
                                        <geom size="0.0095 0.014 0.00045" pos="0.0095 0 0" type="box" name="finger_2_segment_link_6_geom_collision"/>
                                        <body name="finger_2_segment_link_7" pos="0.019 0 0">
                                            <inertial pos="0 0 0" quat="0 0.707107 0 0.707107" mass="0.00633333" diaginertia="1.17589e-06 7.62539e-07 4.14205e-07"/>
                                            <joint name="finger_2_segment_joint_6" pos="0 0 0" axis="0 1 0" limited="true" range="-1 1" damping="0.01" stiffness="5"/>
                                            <geom size="0.0095 0.014 0.00045" pos="0.0095 0 0" type="box" contype="0" conaffinity="0" group="1" name="finger_2_segment_link_7_geom_visual"/>
                                            <geom size="0.0095 0.014 0.00045" pos="0.0095 0 0" type="box" name="finger_2_segment_link_7_geom_collision"/>
                                            <body name="finger_2_segment_link_8" pos="0.019 0 0">
                                                <inertial pos="0 0 0" quat="0 0.707107 0 0.707107" mass="0.00633333" diaginertia="1.17589e-06 7.62539e-07 4.14205e-07"/>
                                                <joint name="finger_2_segment_joint_7" pos="0 0 0" axis="0 1 0" limited="true" range="-1 1" damping="0.01" stiffness="5"/>
                                                <geom size="0.0095 0.014 0.00045" pos="0.0095 0 0" type="box" contype="0" conaffinity="0" group="1" name="finger_2_segment_link_8_geom_visual"/>
                                                <geom size="0.0095 0.014 0.00045" pos="0.0095 0 0" type="box" name="finger_2_segment_link_8_geom_collision"/>
                                                <body name="finger_2_segment_link_9" pos="0.019 0 0">
                                                    <inertial pos="0 0 0" quat="0 0.707107 0 0.707107" mass="0.00633333" diaginertia="1.17589e-06 7.62539e-07 4.14205e-07"/>
                                                    <joint name="finger_2_segment_joint_8" pos="0 0 0" axis="0 1 0" limited="true" range="-1 1" damping="0.01" stiffness="5"/>
                                                    <geom size="0.0095 0.014 0.00045" pos="0.0095 0 0" type="box" contype="0" conaffinity="0" group="1" name="finger_2_segment_link_9_geom_visual"/>
                                                    <geom size="0.0095 0.014 0.00045" pos="0.0095 0 0" type="box" name="finger_2_segment_link_9_geom_collision"/>
                                                    <body name="finger_2_segment_link_10" pos="0.019 0 0">
                                                        <inertial pos="0.0095 0 0" quat="0 0.707107 0 0.707107" mass="0.0126667" diaginertia="2.73326e-06 2.66824e-06 1.59009e-06"/>
                                                        <joint name="finger_2_segment_joint_9" pos="0 0 0" axis="0 1 0" limited="true" range="-1 1" damping="0.01" stiffness="5"/>
                                                        <geom size="0.0095 0.014 0.00045" pos="0.0095 0 0" type="box" contype="0" conaffinity="0" group="1" name="finger_2_segment_link_10_geom_visual"/>
                                                        <geom size="0.0095 0.014 0.00045" pos="0.0095 0 0" type="box" name="finger_2_segment_link_10_geom_collision"/>
                                                        <geom size="0.0175 0.014 0.00045" pos="0.019 0 0.0175" quat="0.707107 0 -0.707107 0" type="box" contype="0" conaffinity="0" group="1" name="finger_2_segment_link_10_geom_hook_visual"/>
                                                        <geom size="0.0175 0.014 0.00045" pos="0.019 0 0.0175" quat="0.707107 0 -0.707107 0" type="box" name="finger_2_segment_link_10_geom_hook_collision"/>
                                                    </body>
                                                </body>
                                            </body>
                                        </body>
                                    </body>
                                </body>
                            </body>
                        </body>
                    </body>
                </body>
            </body>
            <body name="finger_3_intermediate" pos="0 0 0" quat="-0.353553 -0.612372 0.353553 -0.612372">
                <inertial pos="0 0 0" quat="0.37634 0.403447 0.585982 0.593484" mass="0.1" diaginertia="0.000166494 0.00015418 3.54554e-05"/>
                <joint name="finger_3_prismatic_joint" pos="0 0 0" axis="0 1 0" type="slide" limited="true" range="0.053 0.141" damping="1"/>
                <geom type="mesh" contype="0" conaffinity="0" group="1" mesh="nut visual"/>
                <geom type="mesh" mesh="nut collision"/>
                <body name="finger_3" pos="0 0 0">
                    <inertial pos="0.00768339 -0.000416928 0" quat="0.305036 0.562694 0.431992 0.635383" mass="0.106333" diaginertia="0.000255821 0.000253984 4.74922e-05"/>
                    <joint name="finger_3_revolute_joint" pos="0 0 0" axis="0 0 1" limited="true" range="-0.7 0.7" damping="1"/>
                    <geom type="mesh" contype="0" conaffinity="0" group="1" mesh="platform only visual"/>
                    <geom type="mesh" mesh="platform only collision"/>
                    <geom size="0.0095 0.014 0.00045" pos="0.1385 -0.007 0" quat="0.707107 0.707107 0 0" type="box" contype="0" conaffinity="0" group="1"/>
                    <geom size="0.0095 0.014 0.00045" pos="0.1385 -0.007 0" quat="0.707107 0.707107 0 0" type="box"/>
                    <body name="finger_3_segment_link_2" pos="0.148 -0.007 0" quat="0.707107 0.707107 0 0">
                        <inertial pos="0 0 0" quat="0 0.707107 0 0.707107" mass="0.00633333" diaginertia="1.17589e-06 7.62539e-07 4.14205e-07"/>
                        <joint name="finger_3_segment_joint_1" pos="0 0 0" axis="0 1 0" limited="true" range="-1 1" damping="0.01" stiffness="5"/>
                        <geom size="0.0095 0.014 0.00045" pos="0.0095 0 0" type="box" contype="0" conaffinity="0" group="1" name="finger_3_segment_link_2_geom_visual"/>
                        <geom size="0.0095 0.014 0.00045" pos="0.0095 0 0" type="box" name="finger_3_segment_link_2_geom_collision"/>
                        <body name="finger_3_segment_link_3" pos="0.019 0 0">
                            <inertial pos="0 0 0" quat="0 0.707107 0 0.707107" mass="0.00633333" diaginertia="1.17589e-06 7.62539e-07 4.14205e-07"/>
                            <joint name="finger_3_segment_joint_2" pos="0 0 0" axis="0 1 0" limited="true" range="-1 1" damping="0.01" stiffness="5"/>
                            <geom size="0.0095 0.014 0.00045" pos="0.0095 0 0" type="box" contype="0" conaffinity="0" group="1" name="finger_3_segment_link_3_geom_visual"/>
                            <geom size="0.0095 0.014 0.00045" pos="0.0095 0 0" type="box" name="finger_3_segment_link_3_geom_collision"/>
                            <body name="finger_3_segment_link_4" pos="0.019 0 0">
                                <inertial pos="0 0 0" quat="0 0.707107 0 0.707107" mass="0.00633333" diaginertia="1.17589e-06 7.62539e-07 4.14205e-07"/>
                                <joint name="finger_3_segment_joint_3" pos="0 0 0" axis="0 1 0" limited="true" range="-1 1" damping="0.01" stiffness="5"/>
                                <geom size="0.0095 0.014 0.00045" pos="0.0095 0 0" type="box" contype="0" conaffinity="0" group="1" name="finger_3_segment_link_4_geom_visual"/>
                                <geom size="0.0095 0.014 0.00045" pos="0.0095 0 0" type="box" name="finger_3_segment_link_4_geom_collision"/>
                                <body name="finger_3_segment_link_5" pos="0.019 0 0">
                                    <inertial pos="0 0 0" quat="0 0.707107 0 0.707107" mass="0.00633333" diaginertia="1.17589e-06 7.62539e-07 4.14205e-07"/>
                                    <joint name="finger_3_segment_joint_4" pos="0 0 0" axis="0 1 0" limited="true" range="-1 1" damping="0.01" stiffness="5"/>
                                    <geom size="0.0095 0.014 0.00045" pos="0.0095 0 0" type="box" contype="0" conaffinity="0" group="1" name="finger_3_segment_link_5_geom_visual"/>
                                    <geom size="0.0095 0.014 0.00045" pos="0.0095 0 0" type="box" name="finger_3_segment_link_5_geom_collision"/>
                                    <body name="finger_3_segment_link_6" pos="0.019 0 0">
                                        <inertial pos="0 0 0" quat="0 0.707107 0 0.707107" mass="0.00633333" diaginertia="1.17589e-06 7.62539e-07 4.14205e-07"/>
                                        <joint name="finger_3_segment_joint_5" pos="0 0 0" axis="0 1 0" limited="true" range="-1 1" damping="0.01" stiffness="5"/>
                                        <geom size="0.0095 0.014 0.00045" pos="0.0095 0 0" type="box" contype="0" conaffinity="0" group="1" name="finger_3_segment_link_6_geom_visual"/>
                                        <geom size="0.0095 0.014 0.00045" pos="0.0095 0 0" type="box" name="finger_3_segment_link_6_geom_collision"/>
                                        <body name="finger_3_segment_link_7" pos="0.019 0 0">
                                            <inertial pos="0 0 0" quat="0 0.707107 0 0.707107" mass="0.00633333" diaginertia="1.17589e-06 7.62539e-07 4.14205e-07"/>
                                            <joint name="finger_3_segment_joint_6" pos="0 0 0" axis="0 1 0" limited="true" range="-1 1" damping="0.01" stiffness="5"/>
                                            <geom size="0.0095 0.014 0.00045" pos="0.0095 0 0" type="box" contype="0" conaffinity="0" group="1" name="finger_3_segment_link_7_geom_visual"/>
                                            <geom size="0.0095 0.014 0.00045" pos="0.0095 0 0" type="box" name="finger_3_segment_link_7_geom_collision"/>
                                            <body name="finger_3_segment_link_8" pos="0.019 0 0">
                                                <inertial pos="0 0 0" quat="0 0.707107 0 0.707107" mass="0.00633333" diaginertia="1.17589e-06 7.62539e-07 4.14205e-07"/>
                                                <joint name="finger_3_segment_joint_7" pos="0 0 0" axis="0 1 0" limited="true" range="-1 1" damping="0.01" stiffness="5"/>
                                                <geom size="0.0095 0.014 0.00045" pos="0.0095 0 0" type="box" contype="0" conaffinity="0" group="1" name="finger_3_segment_link_8_geom_visual"/>
                                                <geom size="0.0095 0.014 0.00045" pos="0.0095 0 0" type="box" name="finger_3_segment_link_8_geom_collision"/>
                                                <body name="finger_3_segment_link_9" pos="0.019 0 0">
                                                    <inertial pos="0 0 0" quat="0 0.707107 0 0.707107" mass="0.00633333" diaginertia="1.17589e-06 7.62539e-07 4.14205e-07"/>
                                                    <joint name="finger_3_segment_joint_8" pos="0 0 0" axis="0 1 0" limited="true" range="-1 1" damping="0.01" stiffness="5"/>
                                                    <geom size="0.0095 0.014 0.00045" pos="0.0095 0 0" type="box" contype="0" conaffinity="0" group="1" name="finger_3_segment_link_9_geom_visual"/>
                                                    <geom size="0.0095 0.014 0.00045" pos="0.0095 0 0" type="box" name="finger_3_segment_link_9_geom_collision"/>
                                                    <body name="finger_3_segment_link_10" pos="0.019 0 0">
                                                        <inertial pos="0.0095 0 0" quat="0 0.707107 0 0.707107" mass="0.0126667" diaginertia="2.73326e-06 2.66824e-06 1.59009e-06"/>
                                                        <joint name="finger_3_segment_joint_9" pos="0 0 0" axis="0 1 0" limited="true" range="-1 1" damping="0.01" stiffness="5"/>
                                                        <geom size="0.0095 0.014 0.00045" pos="0.0095 0 0" type="box" contype="0" conaffinity="0" group="1" name="finger_3_segment_link_10_geom_visual"/>
                                                        <geom size="0.0095 0.014 0.00045" pos="0.0095 0 0" type="box" name="finger_3_segment_link_10_geom_collision"/>
                                                        <geom size="0.0175 0.014 0.00045" pos="0.019 0 0.0175" quat="0.707107 0 -0.707107 0" type="box" contype="0" conaffinity="0" group="1" name="finger_3_segment_link_10_geom_hook_visual"/>
                                                        <geom size="0.0175 0.014 0.00045" pos="0.019 0 0.0175" quat="0.707107 0 -0.707107 0" type="box" name="finger_3_segment_link_10_geom_hook_collision"/>
                                                    </body>
                                                </body>
                                            </body>
                                        </body>
                                    </body>
                                </body>
                            </body>
                        </body>
                    </body>
                </body>
            </body>
            <body name="palm" pos="0 0 0" quat="0.707107 0 -0.707107 0">
                <inertial pos="0 0 0" mass="0.05" diaginertia="1e-05 1e-05 1e-05"/>
                <joint name="palm_prismatic_joint" pos="0 0 0" axis="1 0 0" type="slide" limited="true" range="0 0.16" damping="1"/>
                <geom type="mesh" contype="0" conaffinity="0" group="1" mesh="palm visual" name="palm_geom_visual"/>
                <geom type="mesh" mesh="palm collision" name="palm_geom_collision"/>
            </body>
        </body>
    <include file="../mjcf_include/objects/objects_35.xml"/></worldbody>
<actuator>
    
  <motor name="world_to_base_actuator" joint="world_to_base"/>

    
  <motor name="finger_1_prismatic_joint_actuator" joint="finger_1_prismatic_joint"/>

  <motor name="finger_1_revolute_joint_actuator" joint="finger_1_revolute_joint"/>

  <motor name="finger_2_prismatic_joint_actuator" joint="finger_2_prismatic_joint"/>

  <motor name="finger_2_revolute_joint_actuator" joint="finger_2_revolute_joint"/>

  <motor name="finger_3_prismatic_joint_actuator" joint="finger_3_prismatic_joint"/>

  <motor name="finger_3_revolute_joint_actuator" joint="finger_3_revolute_joint"/>

  <motor name="palm_prismatic_joint_actuator" joint="palm_prismatic_joint"/>

    
  <motor name="finger_1_segment_joint_1_actuator" joint="finger_1_segment_joint_1"/>

  <motor name="finger_1_segment_joint_2_actuator" joint="finger_1_segment_joint_2"/>

  <motor name="finger_1_segment_joint_3_actuator" joint="finger_1_segment_joint_3"/>

  <motor name="finger_1_segment_joint_4_actuator" joint="finger_1_segment_joint_4"/>

  <motor name="finger_1_segment_joint_5_actuator" joint="finger_1_segment_joint_5"/>

  <motor name="finger_1_segment_joint_6_actuator" joint="finger_1_segment_joint_6"/>

  <motor name="finger_1_segment_joint_7_actuator" joint="finger_1_segment_joint_7"/>

  <motor name="finger_1_segment_joint_8_actuator" joint="finger_1_segment_joint_8"/>

  <motor name="finger_1_segment_joint_9_actuator" joint="finger_1_segment_joint_9"/>

  <motor name="finger_2_segment_joint_1_actuator" joint="finger_2_segment_joint_1"/>

  <motor name="finger_2_segment_joint_2_actuator" joint="finger_2_segment_joint_2"/>

  <motor name="finger_2_segment_joint_3_actuator" joint="finger_2_segment_joint_3"/>

  <motor name="finger_2_segment_joint_4_actuator" joint="finger_2_segment_joint_4"/>

  <motor name="finger_2_segment_joint_5_actuator" joint="finger_2_segment_joint_5"/>

  <motor name="finger_2_segment_joint_6_actuator" joint="finger_2_segment_joint_6"/>

  <motor name="finger_2_segment_joint_7_actuator" joint="finger_2_segment_joint_7"/>

  <motor name="finger_2_segment_joint_8_actuator" joint="finger_2_segment_joint_8"/>

  <motor name="finger_2_segment_joint_9_actuator" joint="finger_2_segment_joint_9"/>

  <motor name="finger_3_segment_joint_1_actuator" joint="finger_3_segment_joint_1"/>

  <motor name="finger_3_segment_joint_2_actuator" joint="finger_3_segment_joint_2"/>

  <motor name="finger_3_segment_joint_3_actuator" joint="finger_3_segment_joint_3"/>

  <motor name="finger_3_segment_joint_4_actuator" joint="finger_3_segment_joint_4"/>

  <motor name="finger_3_segment_joint_5_actuator" joint="finger_3_segment_joint_5"/>

  <motor name="finger_3_segment_joint_6_actuator" joint="finger_3_segment_joint_6"/>

  <motor name="finger_3_segment_joint_7_actuator" joint="finger_3_segment_joint_7"/>

  <motor name="finger_3_segment_joint_8_actuator" joint="finger_3_segment_joint_8"/>

  <motor name="finger_3_segment_joint_9_actuator" joint="finger_3_segment_joint_9"/>

  </actuator><keyframe>
    <key name="initial pose" time="0" qpos="0.0 0.14 0.0 0 0 0 0 0 0 0 0 0  0.14 0.0 0 0 0 0 0 0 0 0 0  0.14 0.0 0 0 0 0 0 0 0 0 0  0.0  -0.75 2.0 0.0326 0 0 0 1 -0.25 2.0 0.0526 0 0 0 1 0.25 2.0 0.033225 0 0 0 1 0.75 2.0 0.0379571428571 0 0 0 1 -0.75 2.5 0.0451 0 0 0 1 -0.25 2.5 0.0351 0 0 0 1 0.25 2.5 0.0329571428571 0 0 0 1 0.75 2.5 0.0301 0 0 0 1 -0.75 3.0 0.0676 0 0 0 1 -0.25 3.0 0.023225 0 0 0 1 0.25 3.0 0.0333142857143 0 0 0 1 0.75 3.0 0.0451 0 0 0 1 -0.75 3.5 0.043225 0 0 0 1 -0.25 3.5 0.0290285714286 0 0 0 1 0.25 3.5 0.0397428571429 0 0 0 1 0.75 3.5 0.03135 0 0 0 1 -0.75 4.0 0.0665285714286 0 0 0 1 -0.25 4.0 0.03385 0 0 0 1 0.25 4.0 0.0626 0 0 0 1 0.75 4.0 0.0656882352941 0 0 0 1"/>
  </keyframe></mujoco>