<sdf version='1.6'>
  <model name='panda'>
    <link name='panda_link0'>
      <pose frame=''>0 0 0 0 -0 0</pose>
      <inertial>
        <pose frame=''>0 0 0 0 -0 0</pose>
        <mass>3.06</mass>
        <inertia>
          <ixx>0.3</ixx>
          <ixy>0</ixy>
          <ixz>0</ixz>
          <iyy>0.3</iyy>
          <iyz>0</iyz>
          <izz>0.3</izz>
        </inertia>
      </inertial>
      <collision name='panda_link0_collision'>
        <pose frame=''>0 0 0 0 -0 0</pose>
        <geometry>
          <mesh>
            <scale>1 1 1</scale>
            <uri>model://gripper_description/meshes_panda/collision/link0.stl</uri>
          </mesh>
        </geometry>
        <surface>
          <contact>
            <ode/>
          </contact>
          <friction>
            <ode>
              <mu>0.2</mu>
              <mu2>0.2</mu2>
            </ode>
          </friction>
        </surface>
      </collision>
      <visual name='panda_link0_visual'>
        <pose frame=''>0 0 0 0 -0 0</pose>
        <geometry>
          <mesh>
            <scale>1 1 1</scale>
            <uri>model://gripper_description/meshes_panda/visual/link0.dae</uri>
          </mesh>
        </geometry>
        <material>
          <script>
            <name>Gazebo/White</name>
            <uri>file://media/materials/scripts/gazebo.material</uri>
          </script>
        </material>
      </visual>
      <gravity>1</gravity>
      <velocity_decay/>
    </link>
    <joint name='world_to_base' type='fixed'>
      <child>panda_link0</child>
      <parent>world</parent>
    </joint>
    <link name='panda_link1'>
      <pose frame=''>0 0 0.333 0 -0 0</pose>
      <inertial>
        <pose frame=''>0 0 0 0 -0 0</pose>
        <mass>2.34</mass>
        <inertia>
          <ixx>0.70337</ixx>
          <ixy>-0.000139</ixy>
          <ixz>0.006772</ixz>
          <iyy>0.70661</iyy>
          <iyz>0.019169</iyz>
          <izz>0.009117</izz>
        </inertia>
      </inertial>
      <collision name='panda_link1_collision'>
        <pose frame=''>0 0 0 0 -0 0</pose>
        <geometry>
          <mesh>
            <scale>1 1 1</scale>
            <uri>model://gripper_description/meshes_panda/collision/link1.stl</uri>
          </mesh>
        </geometry>
        <surface>
          <contact>
            <ode/>
          </contact>
          <friction>
            <ode>
              <mu>0.2</mu>
              <mu2>0.2</mu2>
            </ode>
          </friction>
        </surface>
      </collision>
      <visual name='panda_link1_visual'>
        <pose frame=''>0 0 0 0 -0 0</pose>
        <geometry>
          <mesh>
            <scale>1 1 1</scale>
            <uri>model://gripper_description/meshes_panda/visual/link1.dae</uri>
          </mesh>
        </geometry>
        <material>
          <script>
            <name>Gazebo/White</name>
            <uri>file://media/materials/scripts/gazebo.material</uri>
          </script>
        </material>
      </visual>
      <gravity>1</gravity>
      <velocity_decay/>
    </link>
    <joint name='panda_joint1' type='revolute'>
      <child>panda_link1</child>
      <parent>panda_link0</parent>
      <axis>
        <xyz>0 0 1</xyz>
        <limit>
          <lower>-2.8973</lower>
          <upper>2.8973</upper>
          <effort>87</effort>
          <velocity>2.175</velocity>
        </limit>
        <dynamics>
          <damping>1</damping>
          <friction>0</friction>
          <spring_reference>0</spring_reference>
          <spring_stiffness>0</spring_stiffness>
        </dynamics>
        <use_parent_model_frame>0</use_parent_model_frame>
      </axis>
    </joint>
    <link name='panda_link2'>
      <pose frame=''>0 0 0.333 -1.5708 0 0</pose>
      <inertial>
        <pose frame=''>0 0 0 0 -0 0</pose>
        <mass>2.36</mass>
        <inertia>
          <ixx>0.007962</ixx>
          <ixy>-0.003925</ixy>
          <ixz>0.010254</ixz>
          <iyy>0.02811</iyy>
          <iyz>0.000704</iyz>
          <izz>0.025995</izz>
        </inertia>
      </inertial>
      <collision name='panda_link2_collision'>
        <pose frame=''>0 0 0 0 -0 0</pose>
        <geometry>
          <mesh>
            <scale>1 1 1</scale>
            <uri>model://gripper_description/meshes_panda/collision/link2.stl</uri>
          </mesh>
        </geometry>
        <surface>
          <contact>
            <ode/>
          </contact>
          <friction>
            <ode>
              <mu>0.2</mu>
              <mu2>0.2</mu2>
            </ode>
          </friction>
        </surface>
      </collision>
      <visual name='panda_link2_visual'>
        <pose frame=''>0 0 0 0 -0 0</pose>
        <geometry>
          <mesh>
            <scale>1 1 1</scale>
            <uri>model://gripper_description/meshes_panda/visual/link2.dae</uri>
          </mesh>
        </geometry>
        <material>
          <script>
            <name>Gazebo/White</name>
            <uri>file://media/materials/scripts/gazebo.material</uri>
          </script>
        </material>
      </visual>
      <gravity>1</gravity>
      <velocity_decay/>
    </link>
    <joint name='panda_joint2' type='revolute'>
      <child>panda_link2</child>
      <parent>panda_link1</parent>
      <axis>
        <xyz>0 0 1</xyz>
        <limit>
          <lower>-1.7628</lower>
          <upper>1.7628</upper>
          <effort>87</effort>
          <velocity>2.175</velocity>
        </limit>
        <dynamics>
          <damping>1</damping>
          <friction>0</friction>
          <spring_reference>0</spring_reference>
          <spring_stiffness>0</spring_stiffness>
        </dynamics>
        <use_parent_model_frame>0</use_parent_model_frame>
      </axis>
    </joint>
    <link name='panda_link3'>
      <pose frame=''>0 -0 0.649 0 -0 0</pose>
      <inertial>
        <pose frame=''>0 0 0 0 -0 0</pose>
        <mass>2.38</mass>
        <inertia>
          <ixx>0.037242</ixx>
          <ixy>-0.004761</ixy>
          <ixz>-0.011396</ixz>
          <iyy>0.036155</iyy>
          <iyz>-0.012805</iyz>
          <izz>0.01083</izz>
        </inertia>
      </inertial>
      <collision name='panda_link3_collision'>
        <pose frame=''>0 0 0 0 -0 0</pose>
        <geometry>
          <mesh>
            <scale>1 1 1</scale>
            <uri>model://gripper_description/meshes_panda/collision/link3.stl</uri>
          </mesh>
        </geometry>
        <surface>
          <contact>
            <ode/>
          </contact>
          <friction>
            <ode>
              <mu>0.2</mu>
              <mu2>0.2</mu2>
            </ode>
          </friction>
        </surface>
      </collision>
      <visual name='panda_link3_visual'>
        <pose frame=''>0 0 0 0 -0 0</pose>
        <geometry>
          <mesh>
            <scale>1 1 1</scale>
            <uri>model://gripper_description/meshes_panda/visual/link3.dae</uri>
          </mesh>
        </geometry>
        <material>
          <script>
            <name>Gazebo/White</name>
            <uri>file://media/materials/scripts/gazebo.material</uri>
          </script>
        </material>
      </visual>
      <gravity>1</gravity>
      <velocity_decay/>
    </link>
    <joint name='panda_joint3' type='revolute'>
      <child>panda_link3</child>
      <parent>panda_link2</parent>
      <axis>
        <xyz>0 0 1</xyz>
        <limit>
          <lower>-2.8973</lower>
          <upper>2.8973</upper>
          <effort>87</effort>
          <velocity>2.175</velocity>
        </limit>
        <dynamics>
          <damping>1</damping>
          <friction>0</friction>
          <spring_reference>0</spring_reference>
          <spring_stiffness>0</spring_stiffness>
        </dynamics>
        <use_parent_model_frame>0</use_parent_model_frame>
      </axis>
    </joint>
    <link name='panda_link4'>
      <pose frame=''>0.0825 -0 0.649 1.5708 -0 0</pose>
      <inertial>
        <pose frame=''>0 0 0 0 -0 0</pose>
        <mass>2.43</mass>
        <inertia>
          <ixx>0.025853</ixx>
          <ixy>0.007796</ixy>
          <ixz>-0.001332</ixz>
          <iyy>0.019552</iyy>
          <iyz>0.008641</iyz>
          <izz>0.028323</izz>
        </inertia>
      </inertial>
      <collision name='panda_link4_collision'>
        <pose frame=''>0 0 0 0 -0 0</pose>
        <geometry>
          <mesh>
            <scale>1 1 1</scale>
            <uri>model://gripper_description/meshes_panda/collision/link4.stl</uri>
          </mesh>
        </geometry>
        <surface>
          <contact>
            <ode/>
          </contact>
          <friction>
            <ode>
              <mu>0.2</mu>
              <mu2>0.2</mu2>
            </ode>
          </friction>
        </surface>
      </collision>
      <visual name='panda_link4_visual'>
        <pose frame=''>0 0 0 0 -0 0</pose>
        <geometry>
          <mesh>
            <scale>1 1 1</scale>
            <uri>model://gripper_description/meshes_panda/visual/link4.dae</uri>
          </mesh>
        </geometry>
        <material>
          <script>
            <name>Gazebo/White</name>
            <uri>file://media/materials/scripts/gazebo.material</uri>
          </script>
        </material>
      </visual>
      <gravity>1</gravity>
      <velocity_decay/>
    </link>
    <joint name='panda_joint4' type='revolute'>
      <child>panda_link4</child>
      <parent>panda_link3</parent>
      <axis>
        <xyz>0 0 1</xyz>
        <limit>
          <lower>-3.0718</lower>
          <upper>-0.0698</upper>
          <effort>87</effort>
          <velocity>2.175</velocity>
        </limit>
        <dynamics>
          <damping>1</damping>
          <friction>0</friction>
          <spring_reference>0</spring_reference>
          <spring_stiffness>0</spring_stiffness>
        </dynamics>
        <use_parent_model_frame>0</use_parent_model_frame>
      </axis>
    </joint>
    <link name='panda_link5'>
      <pose frame=''>-0 0 1.033 0 -0 0</pose>
      <inertial>
        <pose frame=''>0 0 0 0 -0 0</pose>
        <mass>3.5</mass>
        <inertia>
          <ixx>0.035549</ixx>
          <ixy>-0.002117</ixy>
          <ixz>-0.004037</ixz>
          <iyy>0.029474</iyy>
          <iyz>0.000229</iyz>
          <izz>0.008627</izz>
        </inertia>
      </inertial>
      <collision name='panda_link5_collision'>
        <pose frame=''>0 0 0 0 -0 0</pose>
        <geometry>
          <mesh>
            <scale>1 1 1</scale>
            <uri>model://gripper_description/meshes_panda/collision/link5.stl</uri>
          </mesh>
        </geometry>
        <surface>
          <contact>
            <ode/>
          </contact>
          <friction>
            <ode>
              <mu>0.2</mu>
              <mu2>0.2</mu2>
            </ode>
          </friction>
        </surface>
      </collision>
      <visual name='panda_link5_visual'>
        <pose frame=''>0 0 0 0 -0 0</pose>
        <geometry>
          <mesh>
            <scale>1 1 1</scale>
            <uri>model://gripper_description/meshes_panda/visual/link5.dae</uri>
          </mesh>
        </geometry>
        <material>
          <script>
            <name>Gazebo/White</name>
            <uri>file://media/materials/scripts/gazebo.material</uri>
          </script>
        </material>
      </visual>
      <gravity>1</gravity>
      <velocity_decay/>
    </link>
    <joint name='panda_joint5' type='revolute'>
      <child>panda_link5</child>
      <parent>panda_link4</parent>
      <axis>
        <xyz>0 0 1</xyz>
        <limit>
          <lower>-2.8973</lower>
          <upper>2.8973</upper>
          <effort>12</effort>
          <velocity>2.61</velocity>
        </limit>
        <dynamics>
          <damping>1</damping>
          <friction>0</friction>
          <spring_reference>0</spring_reference>
          <spring_stiffness>0</spring_stiffness>
        </dynamics>
        <use_parent_model_frame>0</use_parent_model_frame>
      </axis>
    </joint>
    <link name='panda_link6'>
      <pose frame=''>-0 0 1.033 1.5708 -0 0</pose>
      <inertial>
        <pose frame=''>0 0 0 0 -0 0</pose>
        <mass>1.47</mass>
        <inertia>
          <ixx>0.001964</ixx>
          <ixy>0.000109</ixy>
          <ixz>-0.001158</ixz>
          <iyy>0.004354</iyy>
          <iyz>0.000341</iyz>
          <izz>0.005433</izz>
        </inertia>
      </inertial>
      <collision name='panda_link6_collision'>
        <pose frame=''>0 0 0 0 -0 0</pose>
        <geometry>
          <mesh>
            <scale>1 1 1</scale>
            <uri>model://gripper_description/meshes_panda/collision/link6.stl</uri>
          </mesh>
        </geometry>
        <surface>
          <contact>
            <ode/>
          </contact>
          <friction>
            <ode>
              <mu>0.2</mu>
              <mu2>0.2</mu2>
            </ode>
          </friction>
        </surface>
      </collision>
      <visual name='panda_link6_visual'>
        <pose frame=''>0 0 0 0 -0 0</pose>
        <geometry>
          <mesh>
            <scale>1 1 1</scale>
            <uri>model://gripper_description/meshes_panda/visual/link6.dae</uri>
          </mesh>
        </geometry>
        <material>
          <script>
            <name>Gazebo/White</name>
            <uri>file://media/materials/scripts/gazebo.material</uri>
          </script>
        </material>
      </visual>
      <gravity>1</gravity>
      <velocity_decay/>
    </link>
    <joint name='panda_joint6' type='revolute'>
      <child>panda_link6</child>
      <parent>panda_link5</parent>
      <axis>
        <xyz>0 0 1</xyz>
        <limit>
          <lower>-0.0175</lower>
          <upper>3.7525</upper>
          <effort>12</effort>
          <velocity>2.61</velocity>
        </limit>
        <dynamics>
          <damping>1</damping>
          <friction>0</friction>
          <spring_reference>0</spring_reference>
          <spring_stiffness>0</spring_stiffness>
        </dynamics>
        <use_parent_model_frame>0</use_parent_model_frame>
      </axis>
    </joint>
    <link name='panda_link7'>
      <pose frame=''>0.088 0 1.033 3.14159 -0 0</pose>
      <inertial>
        <pose frame=''>0 0 0.211538 0 -0 0</pose>
        <mass>1.95</mass>
        <inertia>
          <ixx>0.0488062</ixx>
          <ixy>-0.000363</ixy>
          <ixz>-0.00110005</ixz>
          <iyy>0.0463226</iyy>
          <iyz>-0.000665297</iyz>
          <izz>0.010045</izz>
        </inertia>
      </inertial>
      <collision name='panda_link7_collision'>
        <pose frame=''>0 0 0 0 -0 0</pose>
        <geometry>
          <mesh>
            <scale>1 1 1</scale>
            <uri>model://gripper_description/meshes_panda/collision/link7.stl</uri>
          </mesh>
        </geometry>
      </collision>
      <collision name='panda_link7_fixed_joint_lump__gripper_base_link_collision_1'>
        <pose frame=''>0 0 0.25 0 0 -0.785398</pose>
        <geometry>
          <mesh>
            <scale>1 1 1</scale>
            <uri>model://gripper_description/meshes/main body collision.STL</uri>
          </mesh>
        </geometry>
        <surface>
          <contact>
            <ode/>
          </contact>
          <friction>
            <ode>
              <mu>0.2</mu>
              <mu2>0.2</mu2>
            </ode>
          </friction>
        </surface>
      </collision>
      <visual name='panda_link7_visual'>
        <pose frame=''>0 0 0 0 -0 0</pose>
        <geometry>
          <mesh>
            <scale>1 1 1</scale>
            <uri>model://gripper_description/meshes_panda/visual/link7.dae</uri>
          </mesh>
        </geometry>
      </visual>
      <visual name='panda_link7_fixed_joint_lump__gripper_base_link_visual_1'>
        <pose frame=''>0 0 0.25 0 0 -0.785398</pose>
        <geometry>
          <mesh>
            <scale>1 1 1</scale>
            <uri>model://gripper_description/meshes/main body visual.STL</uri>
          </mesh>
        </geometry>
        <material>
          <script>
            <name>Gazebo/Grey</name>
            <uri>file://media/materials/scripts/gazebo.material</uri>
          </script>
        </material>
      </visual>
      <gravity>1</gravity>
      <velocity_decay/>
    </link>
    <joint name='panda_joint7' type='revolute'>
      <child>panda_link7</child>
      <parent>panda_link6</parent>
      <axis>
        <xyz>0 0 1</xyz>
        <limit>
          <lower>-2.8973</lower>
          <upper>2.8973</upper>
          <effort>12</effort>
          <velocity>2.61</velocity>
        </limit>
        <dynamics>
          <damping>1</damping>
          <friction>0</friction>
          <spring_reference>0</spring_reference>
          <spring_stiffness>0</spring_stiffness>
        </dynamics>
        <use_parent_model_frame>0</use_parent_model_frame>
      </axis>
    </joint>
    <link name='finger_1_intermediate'>
      <pose frame=''>0.088 -0 0.783 -0.785403 1.57079 3.14159</pose>
      <inertial>
        <pose frame=''>0 0 0 0 -0 0</pose>
        <mass>0.1</mass>
        <inertia>
          <ixx>5.559e-05</ixx>
          <ixy>-4.723e-05</ixy>
          <ixz>1.16e-06</ixz>
          <iyy>0.00014636</iyy>
          <iyz>1e-06</iyz>
          <izz>0.00015418</izz>
        </inertia>
      </inertial>
      <collision name='finger_1_intermediate_collision'>
        <pose frame=''>0 0 0 0 -0 0</pose>
        <geometry>
          <mesh>
            <scale>1 1 1</scale>
            <uri>model://gripper_description/meshes/nut collision.STL</uri>
          </mesh>
        </geometry>
        <surface>
          <contact>
            <ode/>
          </contact>
          <friction>
            <ode>
              <mu>0.2</mu>
              <mu2>0.2</mu2>
            </ode>
          </friction>
        </surface>
      </collision>
      <visual name='finger_1_intermediate_visual'>
        <pose frame=''>0 0 0 0 -0 0</pose>
        <geometry>
          <mesh>
            <scale>1 1 1</scale>
            <uri>model://gripper_description/meshes/nut visual.STL</uri>
          </mesh>
        </geometry>
        <material>
          <script>
            <name>Gazebo/Grey</name>
            <uri>file://media/materials/scripts/gazebo.material</uri>
          </script>
        </material>
      </visual>
      <gravity>1</gravity>
      <velocity_decay/>
    </link>
    <joint name='finger_1_prismatic_joint' type='prismatic'>
      <child>finger_1_intermediate</child>
      <parent>panda_link7</parent>
      <axis>
        <xyz>0 1 0</xyz>
        <limit>
          <lower>0.053</lower>
          <upper>0.141</upper>
          <effort>40</effort>
          <velocity>0.015</velocity>
        </limit>
        <dynamics>
          <damping>1</damping>
          <friction>0</friction>
          <spring_reference>0</spring_reference>
          <spring_stiffness>0</spring_stiffness>
        </dynamics>
        <use_parent_model_frame>0</use_parent_model_frame>
      </axis>
    </joint>
    <link name='finger_1'>
      <pose frame=''>0.088 -0 0.783 -0.785403 1.57079 3.14159</pose>
      <inertial>
        <pose frame=''>0.007683 -0.000417 0 0 -0 0</pose>
        <mass>0.106333</mass>
        <inertia>
          <ixx>5.62961e-05</ixx>
          <ixy>-4.18516e-05</ixy>
          <ixz>1.16e-06</ixz>
          <iyy>0.000246652</iyy>
          <iyz>1e-06</iyz>
          <izz>0.00025435</izz>
        </inertia>
      </inertial>
      <collision name='finger_1_collision'>
        <pose frame=''>0 0 0 0 -0 0</pose>
        <geometry>
          <mesh>
            <scale>1 1 1</scale>
            <uri>model://gripper_description/meshes/platform only collision.STL</uri>
          </mesh>
        </geometry>
        <surface>
          <contact>
            <ode/>
          </contact>
          <friction>
            <ode>
              <mu>0.2</mu>
              <mu2>0.2</mu2>
            </ode>
          </friction>
        </surface>
      </collision>
      <collision name='finger_1_segment_link_1_collision_1'>
        <pose frame=''>0.1385 -0.007 0 1.5708 -0 0</pose>
        <geometry>
          <box>
            <size>0.019 0.028 0.0009</size>
          </box>
        </geometry>
        <surface>
          <contact>
            <ode/>
          </contact>
          <friction>
            <ode>
              <mu>0.2</mu>
              <mu2>0.2</mu2>
            </ode>
          </friction>
        </surface>
      </collision>
      <visual name='finger_1_visual'>
        <pose frame=''>0 0 0 0 -0 0</pose>
        <geometry>
          <mesh>
            <scale>1 1 1</scale>
            <uri>model://gripper_description/meshes/platform only visual.STL</uri>
          </mesh>
        </geometry>
        <material>
          <script>
            <name>Gazebo/Grey</name>
            <uri>file://media/materials/scripts/gazebo.material</uri>
          </script>
        </material>
      </visual>
      <visual name='finger_1_segment_link_1_visual_1'>
        <pose frame=''>0.1385 -0.007 0 1.5708 -0 0</pose>
        <geometry>
          <box>
            <size>0.019 0.028 0.0009</size>
          </box>
        </geometry>
        <material>
          <script>
            <name>Gazebo/Grey</name>
            <uri>file://media/materials/scripts/gazebo.material</uri>
          </script>
        </material>
      </visual>
      <velocity_decay/>
      <gravity>1</gravity>
      <velocity_decay/>
    </link>
    <joint name='finger_1_revolute_joint' type='revolute'>
      <child>finger_1</child>
      <parent>finger_1_intermediate</parent>
      <axis>
        <xyz>0 0 1</xyz>
        <limit>
          <lower>-0.7</lower>
          <upper>0.7</upper>
          <effort>40</effort>
          <velocity>0.1</velocity>
        </limit>
        <dynamics>
          <damping>1</damping>
          <friction>0</friction>
          <spring_reference>0</spring_reference>
          <spring_stiffness>0</spring_stiffness>
        </dynamics>
        <use_parent_model_frame>0</use_parent_model_frame>
      </axis>
    </joint>
    <link name='finger_1_segment_link_2'>
      <pose frame=''>0.08305 0.00495 0.635 0.785403 1.57079 3.14159</pose>
      <inertial>
        <pose frame=''>0 0 0 0 -0 0</pose>
        <mass>0.00633333</mass>
        <inertia>
          <ixx>4.14205e-07</ixx>
          <ixy>0</ixy>
          <ixz>0</ixz>
          <iyy>7.62539e-07</iyy>
          <iyz>0</iyz>
          <izz>1.17589e-06</izz>
        </inertia>
      </inertial>
      <collision name='finger_1_segment_link_2_collision'>
        <pose frame=''>0.0095 0 0 0 -0 0</pose>
        <geometry>
          <box>
            <size>0.019 0.028 0.0009</size>
          </box>
        </geometry>
        <surface>
          <contact>
            <ode>
              <max_vel>0</max_vel>
              <min_depth>0.001</min_depth>
            </ode>
          </contact>
          <friction>
            <ode>
              <mu>0.1</mu>
              <mu2>0.1</mu2>
            </ode>
          </friction>
        </surface>
      </collision>
      <visual name='finger_1_segment_link_2_visual'>
        <pose frame=''>0.0095 0 0 0 -0 0</pose>
        <geometry>
          <box>
            <size>0.019 0.028 0.0009</size>
          </box>
        </geometry>
        <material>
          <script>
            <name>Gazebo/Orange</name>
            <uri>file://media/materials/scripts/gazebo.material</uri>
          </script>
        </material>
      </visual>
      <gravity>1</gravity>
      <velocity_decay/>
    </link>
    <joint name='finger_1_segment_joint_1' type='revolute'>
      <child>finger_1_segment_link_2</child>
      <parent>finger_1</parent>
      <axis>
        <xyz>0 1 0</xyz>
        <limit>
          <lower>-1</lower>
          <upper>1</upper>
          <effort>1000</effort>
          <velocity>1</velocity>
        </limit>
        <dynamics>
          <damping>0.001</damping>
          <friction>0</friction>
          <spring_reference>0</spring_reference>
          <spring_stiffness>3</spring_stiffness>
        </dynamics>
        <use_parent_model_frame>0</use_parent_model_frame>
      </axis>
      <physics>
        <provide_feedback>1</provide_feedback>
        <ode>
          <provide_feedback>1</provide_feedback>
          <implicit_spring_damper>1</implicit_spring_damper>
          <cfm_damping>1</cfm_damping>
          <limit>
            <cfm>0</cfm>
            <erp>0.2</erp>
          </limit>
        </ode>
      </physics>
    </joint>
    <link name='finger_1_segment_link_3'>
      <pose frame=''>0.08305 0.00495 0.616 0.785403 1.57079 3.14159</pose>
      <inertial>
        <pose frame=''>0 0 0 0 -0 0</pose>
        <mass>0.00633333</mass>
        <inertia>
          <ixx>4.14205e-07</ixx>
          <ixy>0</ixy>
          <ixz>0</ixz>
          <iyy>7.62539e-07</iyy>
          <iyz>0</iyz>
          <izz>1.17589e-06</izz>
        </inertia>
      </inertial>
      <collision name='finger_1_segment_link_3_collision'>
        <pose frame=''>0.0095 0 0 0 -0 0</pose>
        <geometry>
          <box>
            <size>0.019 0.028 0.0009</size>
          </box>
        </geometry>
        <surface>
          <contact>
            <ode>
              <max_vel>0</max_vel>
              <min_depth>0.001</min_depth>
            </ode>
          </contact>
          <friction>
            <ode>
              <mu>0.1</mu>
              <mu2>0.1</mu2>
            </ode>
          </friction>
        </surface>
      </collision>
      <visual name='finger_1_segment_link_3_visual'>
        <pose frame=''>0.0095 0 0 0 -0 0</pose>
        <geometry>
          <box>
            <size>0.019 0.028 0.0009</size>
          </box>
        </geometry>
        <material>
          <script>
            <name>Gazebo/Orange</name>
            <uri>file://media/materials/scripts/gazebo.material</uri>
          </script>
        </material>
      </visual>
      <gravity>1</gravity>
      <velocity_decay/>
    </link>
    <joint name='finger_1_segment_joint_2' type='revolute'>
      <child>finger_1_segment_link_3</child>
      <parent>finger_1_segment_link_2</parent>
      <axis>
        <xyz>0 1 0</xyz>
        <limit>
          <lower>-1</lower>
          <upper>1</upper>
          <effort>1000</effort>
          <velocity>1</velocity>
        </limit>
        <dynamics>
          <damping>0.001</damping>
          <friction>0</friction>
          <spring_reference>0</spring_reference>
          <spring_stiffness>3</spring_stiffness>
        </dynamics>
        <use_parent_model_frame>0</use_parent_model_frame>
      </axis>
      <physics>
        <provide_feedback>1</provide_feedback>
        <ode>
          <provide_feedback>1</provide_feedback>
          <implicit_spring_damper>1</implicit_spring_damper>
          <cfm_damping>1</cfm_damping>
          <limit>
            <cfm>0</cfm>
            <erp>0.2</erp>
          </limit>
        </ode>
      </physics>
    </joint>
    <link name='finger_1_segment_link_4'>
      <pose frame=''>0.08305 0.00495 0.597 0.785403 1.57079 3.14159</pose>
      <inertial>
        <pose frame=''>0 0 0 0 -0 0</pose>
        <mass>0.00633333</mass>
        <inertia>
          <ixx>4.14205e-07</ixx>
          <ixy>0</ixy>
          <ixz>0</ixz>
          <iyy>7.62539e-07</iyy>
          <iyz>0</iyz>
          <izz>1.17589e-06</izz>
        </inertia>
      </inertial>
      <collision name='finger_1_segment_link_4_collision'>
        <pose frame=''>0.0095 0 0 0 -0 0</pose>
        <geometry>
          <box>
            <size>0.019 0.028 0.0009</size>
          </box>
        </geometry>
        <surface>
          <contact>
            <ode>
              <max_vel>0</max_vel>
              <min_depth>0.001</min_depth>
            </ode>
          </contact>
          <friction>
            <ode>
              <mu>0.1</mu>
              <mu2>0.1</mu2>
            </ode>
          </friction>
        </surface>
      </collision>
      <visual name='finger_1_segment_link_4_visual'>
        <pose frame=''>0.0095 0 0 0 -0 0</pose>
        <geometry>
          <box>
            <size>0.019 0.028 0.0009</size>
          </box>
        </geometry>
        <material>
          <script>
            <name>Gazebo/Orange</name>
            <uri>file://media/materials/scripts/gazebo.material</uri>
          </script>
        </material>
      </visual>
      <gravity>1</gravity>
      <velocity_decay/>
    </link>
    <joint name='finger_1_segment_joint_3' type='revolute'>
      <child>finger_1_segment_link_4</child>
      <parent>finger_1_segment_link_3</parent>
      <axis>
        <xyz>0 1 0</xyz>
        <limit>
          <lower>-1</lower>
          <upper>1</upper>
          <effort>1000</effort>
          <velocity>1</velocity>
        </limit>
        <dynamics>
          <damping>0.001</damping>
          <friction>0</friction>
          <spring_reference>0</spring_reference>
          <spring_stiffness>3</spring_stiffness>
        </dynamics>
        <use_parent_model_frame>0</use_parent_model_frame>
      </axis>
      <physics>
        <provide_feedback>1</provide_feedback>
        <ode>
          <provide_feedback>1</provide_feedback>
          <implicit_spring_damper>1</implicit_spring_damper>
          <cfm_damping>1</cfm_damping>
          <limit>
            <cfm>0</cfm>
            <erp>0.2</erp>
          </limit>
        </ode>
      </physics>
    </joint>
    <link name='finger_1_segment_link_5'>
      <pose frame=''>0.08305 0.00495 0.578 0.785403 1.57079 3.14159</pose>
      <inertial>
        <pose frame=''>0 0 0 0 -0 0</pose>
        <mass>0.00633333</mass>
        <inertia>
          <ixx>4.14205e-07</ixx>
          <ixy>0</ixy>
          <ixz>0</ixz>
          <iyy>7.62539e-07</iyy>
          <iyz>0</iyz>
          <izz>1.17589e-06</izz>
        </inertia>
      </inertial>
      <collision name='finger_1_segment_link_5_collision'>
        <pose frame=''>0.0095 0 0 0 -0 0</pose>
        <geometry>
          <box>
            <size>0.019 0.028 0.0009</size>
          </box>
        </geometry>
        <surface>
          <contact>
            <ode>
              <max_vel>0</max_vel>
              <min_depth>0.001</min_depth>
            </ode>
          </contact>
          <friction>
            <ode>
              <mu>0.1</mu>
              <mu2>0.1</mu2>
            </ode>
          </friction>
        </surface>
      </collision>
      <visual name='finger_1_segment_link_5_visual'>
        <pose frame=''>0.0095 0 0 0 -0 0</pose>
        <geometry>
          <box>
            <size>0.019 0.028 0.0009</size>
          </box>
        </geometry>
        <material>
          <script>
            <name>Gazebo/Orange</name>
            <uri>file://media/materials/scripts/gazebo.material</uri>
          </script>
        </material>
      </visual>
      <gravity>1</gravity>
      <velocity_decay/>
    </link>
    <joint name='finger_1_segment_joint_4' type='revolute'>
      <child>finger_1_segment_link_5</child>
      <parent>finger_1_segment_link_4</parent>
      <axis>
        <xyz>0 1 0</xyz>
        <limit>
          <lower>-1</lower>
          <upper>1</upper>
          <effort>1000</effort>
          <velocity>1</velocity>
        </limit>
        <dynamics>
          <damping>0.001</damping>
          <friction>0</friction>
          <spring_reference>0</spring_reference>
          <spring_stiffness>3</spring_stiffness>
        </dynamics>
        <use_parent_model_frame>0</use_parent_model_frame>
      </axis>
      <physics>
        <provide_feedback>1</provide_feedback>
        <ode>
          <provide_feedback>1</provide_feedback>
          <implicit_spring_damper>1</implicit_spring_damper>
          <cfm_damping>1</cfm_damping>
          <limit>
            <cfm>0</cfm>
            <erp>0.2</erp>
          </limit>
        </ode>
      </physics>
    </joint>
    <link name='finger_1_segment_link_6'>
      <pose frame=''>0.08305 0.00495 0.559 0.785403 1.57079 3.14159</pose>
      <inertial>
        <pose frame=''>0 0 0 0 -0 0</pose>
        <mass>0.00633333</mass>
        <inertia>
          <ixx>4.14205e-07</ixx>
          <ixy>0</ixy>
          <ixz>0</ixz>
          <iyy>7.62539e-07</iyy>
          <iyz>0</iyz>
          <izz>1.17589e-06</izz>
        </inertia>
      </inertial>
      <collision name='finger_1_segment_link_6_collision'>
        <pose frame=''>0.0095 0 0 0 -0 0</pose>
        <geometry>
          <box>
            <size>0.019 0.028 0.0009</size>
          </box>
        </geometry>
        <surface>
          <contact>
            <ode>
              <max_vel>0</max_vel>
              <min_depth>0.001</min_depth>
            </ode>
          </contact>
          <friction>
            <ode>
              <mu>0.1</mu>
              <mu2>0.1</mu2>
            </ode>
          </friction>
        </surface>
      </collision>
      <visual name='finger_1_segment_link_6_visual'>
        <pose frame=''>0.0095 0 0 0 -0 0</pose>
        <geometry>
          <box>
            <size>0.019 0.028 0.0009</size>
          </box>
        </geometry>
        <material>
          <script>
            <name>Gazebo/Orange</name>
            <uri>file://media/materials/scripts/gazebo.material</uri>
          </script>
        </material>
      </visual>
      <gravity>1</gravity>
      <velocity_decay/>
    </link>
    <joint name='finger_1_segment_joint_5' type='revolute'>
      <child>finger_1_segment_link_6</child>
      <parent>finger_1_segment_link_5</parent>
      <axis>
        <xyz>0 1 0</xyz>
        <limit>
          <lower>-1</lower>
          <upper>1</upper>
          <effort>1000</effort>
          <velocity>1</velocity>
        </limit>
        <dynamics>
          <damping>0.001</damping>
          <friction>0</friction>
          <spring_reference>0</spring_reference>
          <spring_stiffness>3</spring_stiffness>
        </dynamics>
        <use_parent_model_frame>0</use_parent_model_frame>
      </axis>
      <physics>
        <provide_feedback>1</provide_feedback>
        <ode>
          <provide_feedback>1</provide_feedback>
          <implicit_spring_damper>1</implicit_spring_damper>
          <cfm_damping>1</cfm_damping>
          <limit>
            <cfm>0</cfm>
            <erp>0.2</erp>
          </limit>
        </ode>
      </physics>
    </joint>
    <link name='finger_1_segment_link_7'>
      <pose frame=''>0.08305 0.00495 0.54 0.785403 1.57079 3.14159</pose>
      <inertial>
        <pose frame=''>0 0 0 0 -0 0</pose>
        <mass>0.00633333</mass>
        <inertia>
          <ixx>4.14205e-07</ixx>
          <ixy>0</ixy>
          <ixz>0</ixz>
          <iyy>7.62539e-07</iyy>
          <iyz>0</iyz>
          <izz>1.17589e-06</izz>
        </inertia>
      </inertial>
      <collision name='finger_1_segment_link_7_collision'>
        <pose frame=''>0.0095 0 0 0 -0 0</pose>
        <geometry>
          <box>
            <size>0.019 0.028 0.0009</size>
          </box>
        </geometry>
        <surface>
          <contact>
            <ode>
              <max_vel>0</max_vel>
              <min_depth>0.001</min_depth>
            </ode>
          </contact>
          <friction>
            <ode>
              <mu>0.1</mu>
              <mu2>0.1</mu2>
            </ode>
          </friction>
        </surface>
      </collision>
      <visual name='finger_1_segment_link_7_visual'>
        <pose frame=''>0.0095 0 0 0 -0 0</pose>
        <geometry>
          <box>
            <size>0.019 0.028 0.0009</size>
          </box>
        </geometry>
        <material>
          <script>
            <name>Gazebo/Orange</name>
            <uri>file://media/materials/scripts/gazebo.material</uri>
          </script>
        </material>
      </visual>
      <gravity>1</gravity>
      <velocity_decay/>
    </link>
    <joint name='finger_1_segment_joint_6' type='revolute'>
      <child>finger_1_segment_link_7</child>
      <parent>finger_1_segment_link_6</parent>
      <axis>
        <xyz>0 1 0</xyz>
        <limit>
          <lower>-1</lower>
          <upper>1</upper>
          <effort>1000</effort>
          <velocity>1</velocity>
        </limit>
        <dynamics>
          <damping>0.001</damping>
          <friction>0</friction>
          <spring_reference>0</spring_reference>
          <spring_stiffness>3</spring_stiffness>
        </dynamics>
        <use_parent_model_frame>0</use_parent_model_frame>
      </axis>
      <physics>
        <provide_feedback>1</provide_feedback>
        <ode>
          <provide_feedback>1</provide_feedback>
          <implicit_spring_damper>1</implicit_spring_damper>
          <cfm_damping>1</cfm_damping>
          <limit>
            <cfm>0</cfm>
            <erp>0.2</erp>
          </limit>
        </ode>
      </physics>
    </joint>
    <link name='finger_1_segment_link_8'>
      <pose frame=''>0.08305 0.00495 0.521 0.785403 1.57079 3.14159</pose>
      <inertial>
        <pose frame=''>0 0 0 0 -0 0</pose>
        <mass>0.00633333</mass>
        <inertia>
          <ixx>4.14205e-07</ixx>
          <ixy>0</ixy>
          <ixz>0</ixz>
          <iyy>7.62539e-07</iyy>
          <iyz>0</iyz>
          <izz>1.17589e-06</izz>
        </inertia>
      </inertial>
      <collision name='finger_1_segment_link_8_collision'>
        <pose frame=''>0.0095 0 0 0 -0 0</pose>
        <geometry>
          <box>
            <size>0.019 0.028 0.0009</size>
          </box>
        </geometry>
        <surface>
          <contact>
            <ode>
              <max_vel>0</max_vel>
              <min_depth>0.001</min_depth>
            </ode>
          </contact>
          <friction>
            <ode>
              <mu>0.1</mu>
              <mu2>0.1</mu2>
            </ode>
          </friction>
        </surface>
      </collision>
      <visual name='finger_1_segment_link_8_visual'>
        <pose frame=''>0.0095 0 0 0 -0 0</pose>
        <geometry>
          <box>
            <size>0.019 0.028 0.0009</size>
          </box>
        </geometry>
        <material>
          <script>
            <name>Gazebo/Orange</name>
            <uri>file://media/materials/scripts/gazebo.material</uri>
          </script>
        </material>
      </visual>
      <gravity>1</gravity>
      <velocity_decay/>
    </link>
    <joint name='finger_1_segment_joint_7' type='revolute'>
      <child>finger_1_segment_link_8</child>
      <parent>finger_1_segment_link_7</parent>
      <axis>
        <xyz>0 1 0</xyz>
        <limit>
          <lower>-1</lower>
          <upper>1</upper>
          <effort>1000</effort>
          <velocity>1</velocity>
        </limit>
        <dynamics>
          <damping>0.001</damping>
          <friction>0</friction>
          <spring_reference>0</spring_reference>
          <spring_stiffness>3</spring_stiffness>
        </dynamics>
        <use_parent_model_frame>0</use_parent_model_frame>
      </axis>
      <physics>
        <provide_feedback>1</provide_feedback>
        <ode>
          <provide_feedback>1</provide_feedback>
          <implicit_spring_damper>1</implicit_spring_damper>
          <cfm_damping>1</cfm_damping>
          <limit>
            <cfm>0</cfm>
            <erp>0.2</erp>
          </limit>
        </ode>
      </physics>
    </joint>
    <link name='finger_1_segment_link_9'>
      <pose frame=''>0.08305 0.00495 0.502 0.785403 1.57079 3.14159</pose>
      <inertial>
        <pose frame=''>0 0 0 0 -0 0</pose>
        <mass>0.00633333</mass>
        <inertia>
          <ixx>4.14205e-07</ixx>
          <ixy>0</ixy>
          <ixz>0</ixz>
          <iyy>7.62539e-07</iyy>
          <iyz>0</iyz>
          <izz>1.17589e-06</izz>
        </inertia>
      </inertial>
      <collision name='finger_1_segment_link_9_collision'>
        <pose frame=''>0.0095 0 0 0 -0 0</pose>
        <geometry>
          <box>
            <size>0.019 0.028 0.0009</size>
          </box>
        </geometry>
        <surface>
          <contact>
            <ode>
              <max_vel>0</max_vel>
              <min_depth>0.001</min_depth>
            </ode>
          </contact>
          <friction>
            <ode>
              <mu>0.1</mu>
              <mu2>0.1</mu2>
            </ode>
          </friction>
        </surface>
      </collision>
      <visual name='finger_1_segment_link_9_visual'>
        <pose frame=''>0.0095 0 0 0 -0 0</pose>
        <geometry>
          <box>
            <size>0.019 0.028 0.0009</size>
          </box>
        </geometry>
        <material>
          <script>
            <name>Gazebo/Orange</name>
            <uri>file://media/materials/scripts/gazebo.material</uri>
          </script>
        </material>
      </visual>
      <gravity>1</gravity>
      <velocity_decay/>
    </link>
    <joint name='finger_1_segment_joint_8' type='revolute'>
      <child>finger_1_segment_link_9</child>
      <parent>finger_1_segment_link_8</parent>
      <axis>
        <xyz>0 1 0</xyz>
        <limit>
          <lower>-1</lower>
          <upper>1</upper>
          <effort>1000</effort>
          <velocity>1</velocity>
        </limit>
        <dynamics>
          <damping>0.001</damping>
          <friction>0</friction>
          <spring_reference>0</spring_reference>
          <spring_stiffness>3</spring_stiffness>
        </dynamics>
        <use_parent_model_frame>0</use_parent_model_frame>
      </axis>
      <physics>
        <provide_feedback>1</provide_feedback>
        <ode>
          <provide_feedback>1</provide_feedback>
          <implicit_spring_damper>1</implicit_spring_damper>
          <cfm_damping>1</cfm_damping>
          <limit>
            <cfm>0</cfm>
            <erp>0.2</erp>
          </limit>
        </ode>
      </physics>
    </joint>
    <link name='finger_1_segment_link_10'>
      <pose frame=''>0.08305 0.00495 0.483 0.785403 1.57079 3.14159</pose>
      <inertial>
        <pose frame=''>0.0095 0 0 0 -0 0</pose>
        <mass>0.0126667</mass>
        <inertia>
          <ixx>1.59009e-06</ixx>
          <ixy>0</ixy>
          <ixz>-4.66397e-23</ixz>
          <iyy>2.66824e-06</iyy>
          <iyz>0</iyz>
          <izz>2.73326e-06</izz>
        </inertia>
      </inertial>
      <collision name='finger_1_segment_link_10_collision'>
        <pose frame=''>0.0095 0 0 0 -0 0</pose>
        <geometry>
          <box>
            <size>0.019 0.028 0.0009</size>
          </box>
        </geometry>
        <surface>
          <contact>
            <ode>
              <max_vel>0</max_vel>
              <min_depth>0.001</min_depth>
            </ode>
          </contact>
          <friction>
            <ode>
              <mu>0.1</mu>
              <mu2>0.1</mu2>
            </ode>
          </friction>
        </surface>
      </collision>
      <collision name='finger_1_segment_link_10_fixed_joint_lump__finger_1_finger_hook_link_collision_1'>
        <pose frame=''>0.019 0 0.0175 3.14159 -1.57079 3.14159</pose>
        <geometry>
          <box>
            <size>0.035 0.028 0.0009</size>
          </box>
        </geometry>
        <surface>
          <contact>
            <ode>
              <max_vel>0</max_vel>
              <min_depth>0.001</min_depth>
            </ode>
          </contact>
          <friction>
            <ode>
              <mu>0.1</mu>
              <mu2>0.1</mu2>
            </ode>
          </friction>
        </surface>
      </collision>
      <visual name='finger_1_segment_link_10_visual'>
        <pose frame=''>0.0095 0 0 0 -0 0</pose>
        <geometry>
          <box>
            <size>0.019 0.028 0.0009</size>
          </box>
        </geometry>
        <material>
          <script>
            <name>Gazebo/Orange</name>
            <uri>file://media/materials/scripts/gazebo.material</uri>
          </script>
        </material>
      </visual>
      <visual name='finger_1_segment_link_10_fixed_joint_lump__finger_1_finger_hook_link_visual_1'>
        <pose frame=''>0.019 0 0.0175 3.14159 -1.57079 3.14159</pose>
        <geometry>
          <box>
            <size>0.035 0.028 0.0009</size>
          </box>
        </geometry>
        <material>
          <script>
            <name>Gazebo/Orange</name>
            <uri>file://media/materials/scripts/gazebo.material</uri>
          </script>
        </material>
      </visual>
      <velocity_decay/>
      <gravity>1</gravity>
      <velocity_decay/>
    </link>
    <joint name='finger_1_segment_joint_9' type='revolute'>
      <child>finger_1_segment_link_10</child>
      <parent>finger_1_segment_link_9</parent>
      <axis>
        <xyz>0 1 0</xyz>
        <limit>
          <lower>-1</lower>
          <upper>1</upper>
          <effort>1000</effort>
          <velocity>1</velocity>
        </limit>
        <dynamics>
          <damping>0.001</damping>
          <friction>0</friction>
          <spring_reference>0</spring_reference>
          <spring_stiffness>3</spring_stiffness>
        </dynamics>
        <use_parent_model_frame>0</use_parent_model_frame>
      </axis>
      <physics>
        <provide_feedback>1</provide_feedback>
        <ode>
          <provide_feedback>1</provide_feedback>
          <implicit_spring_damper>1</implicit_spring_damper>
          <cfm_damping>1</cfm_damping>
          <limit>
            <cfm>0</cfm>
            <erp>0.2</erp>
          </limit>
        </ode>
      </physics>
    </joint>
    <link name='finger_2_intermediate'>
      <pose frame=''>0.088 -0 0.783 -2.87979 1.57079 3.14159</pose>
      <inertial>
        <pose frame=''>0 0 0 0 -0 0</pose>
        <mass>0.1</mass>
        <inertia>
          <ixx>5.559e-05</ixx>
          <ixy>-4.723e-05</ixy>
          <ixz>1.16e-06</ixz>
          <iyy>0.00014636</iyy>
          <iyz>1e-06</iyz>
          <izz>0.00015418</izz>
        </inertia>
      </inertial>
      <collision name='finger_2_intermediate_collision'>
        <pose frame=''>0 0 0 0 -0 0</pose>
        <geometry>
          <mesh>
            <scale>1 1 1</scale>
            <uri>model://gripper_description/meshes/nut collision.STL</uri>
          </mesh>
        </geometry>
        <surface>
          <contact>
            <ode/>
          </contact>
          <friction>
            <ode>
              <mu>0.2</mu>
              <mu2>0.2</mu2>
            </ode>
          </friction>
        </surface>
      </collision>
      <visual name='finger_2_intermediate_visual'>
        <pose frame=''>0 0 0 0 -0 0</pose>
        <geometry>
          <mesh>
            <scale>1 1 1</scale>
            <uri>model://gripper_description/meshes/nut visual.STL</uri>
          </mesh>
        </geometry>
        <material>
          <script>
            <name>Gazebo/Grey</name>
            <uri>file://media/materials/scripts/gazebo.material</uri>
          </script>
        </material>
      </visual>
      <gravity>1</gravity>
      <velocity_decay/>
    </link>
    <joint name='finger_2_prismatic_joint' type='prismatic'>
      <child>finger_2_intermediate</child>
      <parent>panda_link7</parent>
      <axis>
        <xyz>0 1 0</xyz>
        <limit>
          <lower>0.053</lower>
          <upper>0.141</upper>
          <effort>40</effort>
          <velocity>0.015</velocity>
        </limit>
        <dynamics>
          <damping>1</damping>
          <friction>0</friction>
          <spring_reference>0</spring_reference>
          <spring_stiffness>0</spring_stiffness>
        </dynamics>
        <use_parent_model_frame>0</use_parent_model_frame>
      </axis>
    </joint>
    <link name='finger_2'>
      <pose frame=''>0.088 -0 0.783 -2.87979 1.57079 3.14159</pose>
      <inertial>
        <pose frame=''>0.007683 -0.000417 0 0 -0 0</pose>
        <mass>0.106333</mass>
        <inertia>
          <ixx>5.62961e-05</ixx>
          <ixy>-4.18516e-05</ixy>
          <ixz>1.16e-06</ixz>
          <iyy>0.000246652</iyy>
          <iyz>1e-06</iyz>
          <izz>0.00025435</izz>
        </inertia>
      </inertial>
      <collision name='finger_2_collision'>
        <pose frame=''>0 0 0 0 -0 0</pose>
        <geometry>
          <mesh>
            <scale>1 1 1</scale>
            <uri>model://gripper_description/meshes/platform only collision.STL</uri>
          </mesh>
        </geometry>
        <surface>
          <contact>
            <ode/>
          </contact>
          <friction>
            <ode>
              <mu>0.2</mu>
              <mu2>0.2</mu2>
            </ode>
          </friction>
        </surface>
      </collision>
      <collision name='finger_2_segment_link_1_collision_1'>
        <pose frame=''>0.1385 -0.007 0 1.5708 -0 0</pose>
        <geometry>
          <box>
            <size>0.019 0.028 0.0009</size>
          </box>
        </geometry>
        <surface>
          <contact>
            <ode/>
          </contact>
          <friction>
            <ode>
              <mu>0.2</mu>
              <mu2>0.2</mu2>
            </ode>
          </friction>
        </surface>
      </collision>
      <visual name='finger_2_visual'>
        <pose frame=''>0 0 0 0 -0 0</pose>
        <geometry>
          <mesh>
            <scale>1 1 1</scale>
            <uri>model://gripper_description/meshes/platform only visual.STL</uri>
          </mesh>
        </geometry>
        <material>
          <script>
            <name>Gazebo/Grey</name>
            <uri>file://media/materials/scripts/gazebo.material</uri>
          </script>
        </material>
      </visual>
      <visual name='finger_2_segment_link_1_visual_1'>
        <pose frame=''>0.1385 -0.007 0 1.5708 -0 0</pose>
        <geometry>
          <box>
            <size>0.019 0.028 0.0009</size>
          </box>
        </geometry>
        <material>
          <script>
            <name>Gazebo/Grey</name>
            <uri>file://media/materials/scripts/gazebo.material</uri>
          </script>
        </material>
      </visual>
      <velocity_decay/>
      <gravity>1</gravity>
      <velocity_decay/>
    </link>
    <joint name='finger_2_revolute_joint' type='revolute'>
      <child>finger_2</child>
      <parent>finger_2_intermediate</parent>
      <axis>
        <xyz>0 0 1</xyz>
        <limit>
          <lower>-0.7</lower>
          <upper>0.7</upper>
          <effort>40</effort>
          <velocity>0.1</velocity>
        </limit>
        <dynamics>
          <damping>1</damping>
          <friction>0</friction>
          <spring_reference>0</spring_reference>
          <spring_stiffness>0</spring_stiffness>
        </dynamics>
        <use_parent_model_frame>0</use_parent_model_frame>
      </axis>
    </joint>
    <link name='finger_2_segment_link_2'>
      <pose frame=''>0.086188 -0.006761 0.635 -1.30899 1.57079 -3.14159</pose>
      <inertial>
        <pose frame=''>0 0 0 0 -0 0</pose>
        <mass>0.00633333</mass>
        <inertia>
          <ixx>4.14205e-07</ixx>
          <ixy>0</ixy>
          <ixz>0</ixz>
          <iyy>7.62539e-07</iyy>
          <iyz>0</iyz>
          <izz>1.17589e-06</izz>
        </inertia>
      </inertial>
      <collision name='finger_2_segment_link_2_collision'>
        <pose frame=''>0.0095 0 0 0 -0 0</pose>
        <geometry>
          <box>
            <size>0.019 0.028 0.0009</size>
          </box>
        </geometry>
        <surface>
          <contact>
            <ode>
              <max_vel>0</max_vel>
              <min_depth>0.001</min_depth>
            </ode>
          </contact>
          <friction>
            <ode>
              <mu>0.1</mu>
              <mu2>0.1</mu2>
            </ode>
          </friction>
        </surface>
      </collision>
      <visual name='finger_2_segment_link_2_visual'>
        <pose frame=''>0.0095 0 0 0 -0 0</pose>
        <geometry>
          <box>
            <size>0.019 0.028 0.0009</size>
          </box>
        </geometry>
        <material>
          <script>
            <name>Gazebo/Orange</name>
            <uri>file://media/materials/scripts/gazebo.material</uri>
          </script>
        </material>
      </visual>
      <gravity>1</gravity>
      <velocity_decay/>
    </link>
    <joint name='finger_2_segment_joint_1' type='revolute'>
      <child>finger_2_segment_link_2</child>
      <parent>finger_2</parent>
      <axis>
        <xyz>0 1 0</xyz>
        <limit>
          <lower>-1</lower>
          <upper>1</upper>
          <effort>1000</effort>
          <velocity>1</velocity>
        </limit>
        <dynamics>
          <damping>0.001</damping>
          <friction>0</friction>
          <spring_reference>0</spring_reference>
          <spring_stiffness>3</spring_stiffness>
        </dynamics>
        <use_parent_model_frame>0</use_parent_model_frame>
      </axis>
      <physics>
        <provide_feedback>1</provide_feedback>
        <ode>
          <provide_feedback>1</provide_feedback>
          <implicit_spring_damper>1</implicit_spring_damper>
          <cfm_damping>1</cfm_damping>
          <limit>
            <cfm>0</cfm>
            <erp>0.2</erp>
          </limit>
        </ode>
      </physics>
    </joint>
    <link name='finger_2_segment_link_3'>
      <pose frame=''>0.086188 -0.006761 0.616 -1.30899 1.57079 -3.14159</pose>
      <inertial>
        <pose frame=''>0 0 0 0 -0 0</pose>
        <mass>0.00633333</mass>
        <inertia>
          <ixx>4.14205e-07</ixx>
          <ixy>0</ixy>
          <ixz>0</ixz>
          <iyy>7.62539e-07</iyy>
          <iyz>0</iyz>
          <izz>1.17589e-06</izz>
        </inertia>
      </inertial>
      <collision name='finger_2_segment_link_3_collision'>
        <pose frame=''>0.0095 0 0 0 -0 0</pose>
        <geometry>
          <box>
            <size>0.019 0.028 0.0009</size>
          </box>
        </geometry>
        <surface>
          <contact>
            <ode>
              <max_vel>0</max_vel>
              <min_depth>0.001</min_depth>
            </ode>
          </contact>
          <friction>
            <ode>
              <mu>0.1</mu>
              <mu2>0.1</mu2>
            </ode>
          </friction>
        </surface>
      </collision>
      <visual name='finger_2_segment_link_3_visual'>
        <pose frame=''>0.0095 0 0 0 -0 0</pose>
        <geometry>
          <box>
            <size>0.019 0.028 0.0009</size>
          </box>
        </geometry>
        <material>
          <script>
            <name>Gazebo/Orange</name>
            <uri>file://media/materials/scripts/gazebo.material</uri>
          </script>
        </material>
      </visual>
      <gravity>1</gravity>
      <velocity_decay/>
    </link>
    <joint name='finger_2_segment_joint_2' type='revolute'>
      <child>finger_2_segment_link_3</child>
      <parent>finger_2_segment_link_2</parent>
      <axis>
        <xyz>0 1 0</xyz>
        <limit>
          <lower>-1</lower>
          <upper>1</upper>
          <effort>1000</effort>
          <velocity>1</velocity>
        </limit>
        <dynamics>
          <damping>0.001</damping>
          <friction>0</friction>
          <spring_reference>0</spring_reference>
          <spring_stiffness>3</spring_stiffness>
        </dynamics>
        <use_parent_model_frame>0</use_parent_model_frame>
      </axis>
      <physics>
        <provide_feedback>1</provide_feedback>
        <ode>
          <provide_feedback>1</provide_feedback>
          <implicit_spring_damper>1</implicit_spring_damper>
          <cfm_damping>1</cfm_damping>
          <limit>
            <cfm>0</cfm>
            <erp>0.2</erp>
          </limit>
        </ode>
      </physics>
    </joint>
    <link name='finger_2_segment_link_4'>
      <pose frame=''>0.086188 -0.006761 0.597 -1.30899 1.57079 -3.14159</pose>
      <inertial>
        <pose frame=''>0 0 0 0 -0 0</pose>
        <mass>0.00633333</mass>
        <inertia>
          <ixx>4.14205e-07</ixx>
          <ixy>0</ixy>
          <ixz>0</ixz>
          <iyy>7.62539e-07</iyy>
          <iyz>0</iyz>
          <izz>1.17589e-06</izz>
        </inertia>
      </inertial>
      <collision name='finger_2_segment_link_4_collision'>
        <pose frame=''>0.0095 0 0 0 -0 0</pose>
        <geometry>
          <box>
            <size>0.019 0.028 0.0009</size>
          </box>
        </geometry>
        <surface>
          <contact>
            <ode>
              <max_vel>0</max_vel>
              <min_depth>0.001</min_depth>
            </ode>
          </contact>
          <friction>
            <ode>
              <mu>0.1</mu>
              <mu2>0.1</mu2>
            </ode>
          </friction>
        </surface>
      </collision>
      <visual name='finger_2_segment_link_4_visual'>
        <pose frame=''>0.0095 0 0 0 -0 0</pose>
        <geometry>
          <box>
            <size>0.019 0.028 0.0009</size>
          </box>
        </geometry>
        <material>
          <script>
            <name>Gazebo/Orange</name>
            <uri>file://media/materials/scripts/gazebo.material</uri>
          </script>
        </material>
      </visual>
      <gravity>1</gravity>
      <velocity_decay/>
    </link>
    <joint name='finger_2_segment_joint_3' type='revolute'>
      <child>finger_2_segment_link_4</child>
      <parent>finger_2_segment_link_3</parent>
      <axis>
        <xyz>0 1 0</xyz>
        <limit>
          <lower>-1</lower>
          <upper>1</upper>
          <effort>1000</effort>
          <velocity>1</velocity>
        </limit>
        <dynamics>
          <damping>0.001</damping>
          <friction>0</friction>
          <spring_reference>0</spring_reference>
          <spring_stiffness>3</spring_stiffness>
        </dynamics>
        <use_parent_model_frame>0</use_parent_model_frame>
      </axis>
      <physics>
        <provide_feedback>1</provide_feedback>
        <ode>
          <provide_feedback>1</provide_feedback>
          <implicit_spring_damper>1</implicit_spring_damper>
          <cfm_damping>1</cfm_damping>
          <limit>
            <cfm>0</cfm>
            <erp>0.2</erp>
          </limit>
        </ode>
      </physics>
    </joint>
    <link name='finger_2_segment_link_5'>
      <pose frame=''>0.086188 -0.006761 0.578 -1.30899 1.57079 -3.14159</pose>
      <inertial>
        <pose frame=''>0 0 0 0 -0 0</pose>
        <mass>0.00633333</mass>
        <inertia>
          <ixx>4.14205e-07</ixx>
          <ixy>0</ixy>
          <ixz>0</ixz>
          <iyy>7.62539e-07</iyy>
          <iyz>0</iyz>
          <izz>1.17589e-06</izz>
        </inertia>
      </inertial>
      <collision name='finger_2_segment_link_5_collision'>
        <pose frame=''>0.0095 0 0 0 -0 0</pose>
        <geometry>
          <box>
            <size>0.019 0.028 0.0009</size>
          </box>
        </geometry>
        <surface>
          <contact>
            <ode>
              <max_vel>0</max_vel>
              <min_depth>0.001</min_depth>
            </ode>
          </contact>
          <friction>
            <ode>
              <mu>0.1</mu>
              <mu2>0.1</mu2>
            </ode>
          </friction>
        </surface>
      </collision>
      <visual name='finger_2_segment_link_5_visual'>
        <pose frame=''>0.0095 0 0 0 -0 0</pose>
        <geometry>
          <box>
            <size>0.019 0.028 0.0009</size>
          </box>
        </geometry>
        <material>
          <script>
            <name>Gazebo/Orange</name>
            <uri>file://media/materials/scripts/gazebo.material</uri>
          </script>
        </material>
      </visual>
      <gravity>1</gravity>
      <velocity_decay/>
    </link>
    <joint name='finger_2_segment_joint_4' type='revolute'>
      <child>finger_2_segment_link_5</child>
      <parent>finger_2_segment_link_4</parent>
      <axis>
        <xyz>0 1 0</xyz>
        <limit>
          <lower>-1</lower>
          <upper>1</upper>
          <effort>1000</effort>
          <velocity>1</velocity>
        </limit>
        <dynamics>
          <damping>0.001</damping>
          <friction>0</friction>
          <spring_reference>0</spring_reference>
          <spring_stiffness>3</spring_stiffness>
        </dynamics>
        <use_parent_model_frame>0</use_parent_model_frame>
      </axis>
      <physics>
        <provide_feedback>1</provide_feedback>
        <ode>
          <provide_feedback>1</provide_feedback>
          <implicit_spring_damper>1</implicit_spring_damper>
          <cfm_damping>1</cfm_damping>
          <limit>
            <cfm>0</cfm>
            <erp>0.2</erp>
          </limit>
        </ode>
      </physics>
    </joint>
    <link name='finger_2_segment_link_6'>
      <pose frame=''>0.086188 -0.006761 0.559 -1.30899 1.57079 -3.14159</pose>
      <inertial>
        <pose frame=''>0 0 0 0 -0 0</pose>
        <mass>0.00633333</mass>
        <inertia>
          <ixx>4.14205e-07</ixx>
          <ixy>0</ixy>
          <ixz>0</ixz>
          <iyy>7.62539e-07</iyy>
          <iyz>0</iyz>
          <izz>1.17589e-06</izz>
        </inertia>
      </inertial>
      <collision name='finger_2_segment_link_6_collision'>
        <pose frame=''>0.0095 0 0 0 -0 0</pose>
        <geometry>
          <box>
            <size>0.019 0.028 0.0009</size>
          </box>
        </geometry>
        <surface>
          <contact>
            <ode>
              <max_vel>0</max_vel>
              <min_depth>0.001</min_depth>
            </ode>
          </contact>
          <friction>
            <ode>
              <mu>0.1</mu>
              <mu2>0.1</mu2>
            </ode>
          </friction>
        </surface>
      </collision>
      <visual name='finger_2_segment_link_6_visual'>
        <pose frame=''>0.0095 0 0 0 -0 0</pose>
        <geometry>
          <box>
            <size>0.019 0.028 0.0009</size>
          </box>
        </geometry>
        <material>
          <script>
            <name>Gazebo/Orange</name>
            <uri>file://media/materials/scripts/gazebo.material</uri>
          </script>
        </material>
      </visual>
      <gravity>1</gravity>
      <velocity_decay/>
    </link>
    <joint name='finger_2_segment_joint_5' type='revolute'>
      <child>finger_2_segment_link_6</child>
      <parent>finger_2_segment_link_5</parent>
      <axis>
        <xyz>0 1 0</xyz>
        <limit>
          <lower>-1</lower>
          <upper>1</upper>
          <effort>1000</effort>
          <velocity>1</velocity>
        </limit>
        <dynamics>
          <damping>0.001</damping>
          <friction>0</friction>
          <spring_reference>0</spring_reference>
          <spring_stiffness>3</spring_stiffness>
        </dynamics>
        <use_parent_model_frame>0</use_parent_model_frame>
      </axis>
      <physics>
        <provide_feedback>1</provide_feedback>
        <ode>
          <provide_feedback>1</provide_feedback>
          <implicit_spring_damper>1</implicit_spring_damper>
          <cfm_damping>1</cfm_damping>
          <limit>
            <cfm>0</cfm>
            <erp>0.2</erp>
          </limit>
        </ode>
      </physics>
    </joint>
    <link name='finger_2_segment_link_7'>
      <pose frame=''>0.086188 -0.006761 0.54 -1.30899 1.57079 -3.14159</pose>
      <inertial>
        <pose frame=''>0 0 0 0 -0 0</pose>
        <mass>0.00633333</mass>
        <inertia>
          <ixx>4.14205e-07</ixx>
          <ixy>0</ixy>
          <ixz>0</ixz>
          <iyy>7.62539e-07</iyy>
          <iyz>0</iyz>
          <izz>1.17589e-06</izz>
        </inertia>
      </inertial>
      <collision name='finger_2_segment_link_7_collision'>
        <pose frame=''>0.0095 0 0 0 -0 0</pose>
        <geometry>
          <box>
            <size>0.019 0.028 0.0009</size>
          </box>
        </geometry>
        <surface>
          <contact>
            <ode>
              <max_vel>0</max_vel>
              <min_depth>0.001</min_depth>
            </ode>
          </contact>
          <friction>
            <ode>
              <mu>0.1</mu>
              <mu2>0.1</mu2>
            </ode>
          </friction>
        </surface>
      </collision>
      <visual name='finger_2_segment_link_7_visual'>
        <pose frame=''>0.0095 0 0 0 -0 0</pose>
        <geometry>
          <box>
            <size>0.019 0.028 0.0009</size>
          </box>
        </geometry>
        <material>
          <script>
            <name>Gazebo/Orange</name>
            <uri>file://media/materials/scripts/gazebo.material</uri>
          </script>
        </material>
      </visual>
      <gravity>1</gravity>
      <velocity_decay/>
    </link>
    <joint name='finger_2_segment_joint_6' type='revolute'>
      <child>finger_2_segment_link_7</child>
      <parent>finger_2_segment_link_6</parent>
      <axis>
        <xyz>0 1 0</xyz>
        <limit>
          <lower>-1</lower>
          <upper>1</upper>
          <effort>1000</effort>
          <velocity>1</velocity>
        </limit>
        <dynamics>
          <damping>0.001</damping>
          <friction>0</friction>
          <spring_reference>0</spring_reference>
          <spring_stiffness>3</spring_stiffness>
        </dynamics>
        <use_parent_model_frame>0</use_parent_model_frame>
      </axis>
      <physics>
        <provide_feedback>1</provide_feedback>
        <ode>
          <provide_feedback>1</provide_feedback>
          <implicit_spring_damper>1</implicit_spring_damper>
          <cfm_damping>1</cfm_damping>
          <limit>
            <cfm>0</cfm>
            <erp>0.2</erp>
          </limit>
        </ode>
      </physics>
    </joint>
    <link name='finger_2_segment_link_8'>
      <pose frame=''>0.086188 -0.006761 0.521 -1.30899 1.57079 -3.14159</pose>
      <inertial>
        <pose frame=''>0 0 0 0 -0 0</pose>
        <mass>0.00633333</mass>
        <inertia>
          <ixx>4.14205e-07</ixx>
          <ixy>0</ixy>
          <ixz>0</ixz>
          <iyy>7.62539e-07</iyy>
          <iyz>0</iyz>
          <izz>1.17589e-06</izz>
        </inertia>
      </inertial>
      <collision name='finger_2_segment_link_8_collision'>
        <pose frame=''>0.0095 0 0 0 -0 0</pose>
        <geometry>
          <box>
            <size>0.019 0.028 0.0009</size>
          </box>
        </geometry>
        <surface>
          <contact>
            <ode>
              <max_vel>0</max_vel>
              <min_depth>0.001</min_depth>
            </ode>
          </contact>
          <friction>
            <ode>
              <mu>0.1</mu>
              <mu2>0.1</mu2>
            </ode>
          </friction>
        </surface>
      </collision>
      <visual name='finger_2_segment_link_8_visual'>
        <pose frame=''>0.0095 0 0 0 -0 0</pose>
        <geometry>
          <box>
            <size>0.019 0.028 0.0009</size>
          </box>
        </geometry>
        <material>
          <script>
            <name>Gazebo/Orange</name>
            <uri>file://media/materials/scripts/gazebo.material</uri>
          </script>
        </material>
      </visual>
      <gravity>1</gravity>
      <velocity_decay/>
    </link>
    <joint name='finger_2_segment_joint_7' type='revolute'>
      <child>finger_2_segment_link_8</child>
      <parent>finger_2_segment_link_7</parent>
      <axis>
        <xyz>0 1 0</xyz>
        <limit>
          <lower>-1</lower>
          <upper>1</upper>
          <effort>1000</effort>
          <velocity>1</velocity>
        </limit>
        <dynamics>
          <damping>0.001</damping>
          <friction>0</friction>
          <spring_reference>0</spring_reference>
          <spring_stiffness>3</spring_stiffness>
        </dynamics>
        <use_parent_model_frame>0</use_parent_model_frame>
      </axis>
      <physics>
        <provide_feedback>1</provide_feedback>
        <ode>
          <provide_feedback>1</provide_feedback>
          <implicit_spring_damper>1</implicit_spring_damper>
          <cfm_damping>1</cfm_damping>
          <limit>
            <cfm>0</cfm>
            <erp>0.2</erp>
          </limit>
        </ode>
      </physics>
    </joint>
    <link name='finger_2_segment_link_9'>
      <pose frame=''>0.086188 -0.006761 0.502 -1.30899 1.57079 -3.14159</pose>
      <inertial>
        <pose frame=''>0 0 0 0 -0 0</pose>
        <mass>0.00633333</mass>
        <inertia>
          <ixx>4.14205e-07</ixx>
          <ixy>0</ixy>
          <ixz>0</ixz>
          <iyy>7.62539e-07</iyy>
          <iyz>0</iyz>
          <izz>1.17589e-06</izz>
        </inertia>
      </inertial>
      <collision name='finger_2_segment_link_9_collision'>
        <pose frame=''>0.0095 0 0 0 -0 0</pose>
        <geometry>
          <box>
            <size>0.019 0.028 0.0009</size>
          </box>
        </geometry>
        <surface>
          <contact>
            <ode>
              <max_vel>0</max_vel>
              <min_depth>0.001</min_depth>
            </ode>
          </contact>
          <friction>
            <ode>
              <mu>0.1</mu>
              <mu2>0.1</mu2>
            </ode>
          </friction>
        </surface>
      </collision>
      <visual name='finger_2_segment_link_9_visual'>
        <pose frame=''>0.0095 0 0 0 -0 0</pose>
        <geometry>
          <box>
            <size>0.019 0.028 0.0009</size>
          </box>
        </geometry>
        <material>
          <script>
            <name>Gazebo/Orange</name>
            <uri>file://media/materials/scripts/gazebo.material</uri>
          </script>
        </material>
      </visual>
      <gravity>1</gravity>
      <velocity_decay/>
    </link>
    <joint name='finger_2_segment_joint_8' type='revolute'>
      <child>finger_2_segment_link_9</child>
      <parent>finger_2_segment_link_8</parent>
      <axis>
        <xyz>0 1 0</xyz>
        <limit>
          <lower>-1</lower>
          <upper>1</upper>
          <effort>1000</effort>
          <velocity>1</velocity>
        </limit>
        <dynamics>
          <damping>0.001</damping>
          <friction>0</friction>
          <spring_reference>0</spring_reference>
          <spring_stiffness>3</spring_stiffness>
        </dynamics>
        <use_parent_model_frame>0</use_parent_model_frame>
      </axis>
      <physics>
        <provide_feedback>1</provide_feedback>
        <ode>
          <provide_feedback>1</provide_feedback>
          <implicit_spring_damper>1</implicit_spring_damper>
          <cfm_damping>1</cfm_damping>
          <limit>
            <cfm>0</cfm>
            <erp>0.2</erp>
          </limit>
        </ode>
      </physics>
    </joint>
    <link name='finger_2_segment_link_10'>
      <pose frame=''>0.086188 -0.006761 0.483 -1.30899 1.57079 -3.14159</pose>
      <inertial>
        <pose frame=''>0.0095 0 0 0 -0 0</pose>
        <mass>0.0126667</mass>
        <inertia>
          <ixx>1.59009e-06</ixx>
          <ixy>0</ixy>
          <ixz>-4.66397e-23</ixz>
          <iyy>2.66824e-06</iyy>
          <iyz>0</iyz>
          <izz>2.73326e-06</izz>
        </inertia>
      </inertial>
      <collision name='finger_2_segment_link_10_collision'>
        <pose frame=''>0.0095 0 0 0 -0 0</pose>
        <geometry>
          <box>
            <size>0.019 0.028 0.0009</size>
          </box>
        </geometry>
        <surface>
          <contact>
            <ode>
              <max_vel>0</max_vel>
              <min_depth>0.001</min_depth>
            </ode>
          </contact>
          <friction>
            <ode>
              <mu>0.1</mu>
              <mu2>0.1</mu2>
            </ode>
          </friction>
        </surface>
      </collision>
      <collision name='finger_2_segment_link_10_fixed_joint_lump__finger_2_finger_hook_link_collision_1'>
        <pose frame=''>0.019 0 0.0175 3.14159 -1.57079 3.14159</pose>
        <geometry>
          <box>
            <size>0.035 0.028 0.0009</size>
          </box>
        </geometry>
        <surface>
          <contact>
            <ode>
              <max_vel>0</max_vel>
              <min_depth>0.001</min_depth>
            </ode>
          </contact>
          <friction>
            <ode>
              <mu>0.1</mu>
              <mu2>0.1</mu2>
            </ode>
          </friction>
        </surface>
      </collision>
      <visual name='finger_2_segment_link_10_visual'>
        <pose frame=''>0.0095 0 0 0 -0 0</pose>
        <geometry>
          <box>
            <size>0.019 0.028 0.0009</size>
          </box>
        </geometry>
        <material>
          <script>
            <name>Gazebo/Orange</name>
            <uri>file://media/materials/scripts/gazebo.material</uri>
          </script>
        </material>
      </visual>
      <visual name='finger_2_segment_link_10_fixed_joint_lump__finger_2_finger_hook_link_visual_1'>
        <pose frame=''>0.019 0 0.0175 3.14159 -1.57079 3.14159</pose>
        <geometry>
          <box>
            <size>0.035 0.028 0.0009</size>
          </box>
        </geometry>
        <material>
          <script>
            <name>Gazebo/Orange</name>
            <uri>file://media/materials/scripts/gazebo.material</uri>
          </script>
        </material>
      </visual>
      <velocity_decay/>
      <gravity>1</gravity>
      <velocity_decay/>
    </link>
    <joint name='finger_2_segment_joint_9' type='revolute'>
      <child>finger_2_segment_link_10</child>
      <parent>finger_2_segment_link_9</parent>
      <axis>
        <xyz>0 1 0</xyz>
        <limit>
          <lower>-1</lower>
          <upper>1</upper>
          <effort>1000</effort>
          <velocity>1</velocity>
        </limit>
        <dynamics>
          <damping>0.001</damping>
          <friction>0</friction>
          <spring_reference>0</spring_reference>
          <spring_stiffness>3</spring_stiffness>
        </dynamics>
        <use_parent_model_frame>0</use_parent_model_frame>
      </axis>
      <physics>
        <provide_feedback>1</provide_feedback>
        <ode>
          <provide_feedback>1</provide_feedback>
          <implicit_spring_damper>1</implicit_spring_damper>
          <cfm_damping>1</cfm_damping>
          <limit>
            <cfm>0</cfm>
            <erp>0.2</erp>
          </limit>
        </ode>
      </physics>
    </joint>
    <link name='finger_3_intermediate'>
      <pose frame=''>0.088 -0 0.783 1.30899 1.57079 3.14159</pose>
      <inertial>
        <pose frame=''>0 0 0 0 -0 0</pose>
        <mass>0.1</mass>
        <inertia>
          <ixx>5.559e-05</ixx>
          <ixy>-4.723e-05</ixy>
          <ixz>1.16e-06</ixz>
          <iyy>0.00014636</iyy>
          <iyz>1e-06</iyz>
          <izz>0.00015418</izz>
        </inertia>
      </inertial>
      <collision name='finger_3_intermediate_collision'>
        <pose frame=''>0 0 0 0 -0 0</pose>
        <geometry>
          <mesh>
            <scale>1 1 1</scale>
            <uri>model://gripper_description/meshes/nut collision.STL</uri>
          </mesh>
        </geometry>
        <surface>
          <contact>
            <ode/>
          </contact>
          <friction>
            <ode>
              <mu>0.2</mu>
              <mu2>0.2</mu2>
            </ode>
          </friction>
        </surface>
      </collision>
      <visual name='finger_3_intermediate_visual'>
        <pose frame=''>0 0 0 0 -0 0</pose>
        <geometry>
          <mesh>
            <scale>1 1 1</scale>
            <uri>model://gripper_description/meshes/nut visual.STL</uri>
          </mesh>
        </geometry>
        <material>
          <script>
            <name>Gazebo/Grey</name>
            <uri>file://media/materials/scripts/gazebo.material</uri>
          </script>
        </material>
      </visual>
      <gravity>1</gravity>
      <velocity_decay/>
    </link>
    <joint name='finger_3_prismatic_joint' type='prismatic'>
      <child>finger_3_intermediate</child>
      <parent>panda_link7</parent>
      <axis>
        <xyz>0 1 0</xyz>
        <limit>
          <lower>0.053</lower>
          <upper>0.141</upper>
          <effort>40</effort>
          <velocity>0.015</velocity>
        </limit>
        <dynamics>
          <damping>1</damping>
          <friction>0</friction>
          <spring_reference>0</spring_reference>
          <spring_stiffness>0</spring_stiffness>
        </dynamics>
        <use_parent_model_frame>0</use_parent_model_frame>
      </axis>
    </joint>
    <link name='finger_3'>
      <pose frame=''>0.088 -0 0.783 1.30899 1.57079 3.14159</pose>
      <inertial>
        <pose frame=''>0.007683 -0.000417 0 0 -0 0</pose>
        <mass>0.106333</mass>
        <inertia>
          <ixx>5.62961e-05</ixx>
          <ixy>-4.18516e-05</ixy>
          <ixz>1.16e-06</ixz>
          <iyy>0.000246652</iyy>
          <iyz>1e-06</iyz>
          <izz>0.00025435</izz>
        </inertia>
      </inertial>
      <collision name='finger_3_collision'>
        <pose frame=''>0 0 0 0 -0 0</pose>
        <geometry>
          <mesh>
            <scale>1 1 1</scale>
            <uri>model://gripper_description/meshes/platform only collision.STL</uri>
          </mesh>
        </geometry>
        <surface>
          <contact>
            <ode/>
          </contact>
          <friction>
            <ode>
              <mu>0.2</mu>
              <mu2>0.2</mu2>
            </ode>
          </friction>
        </surface>
      </collision>
      <collision name='finger_3_segment_link_1_collision_1'>
        <pose frame=''>0.1385 -0.007 0 1.5708 -0 0</pose>
        <geometry>
          <box>
            <size>0.019 0.028 0.0009</size>
          </box>
        </geometry>
        <surface>
          <contact>
            <ode/>
          </contact>
          <friction>
            <ode>
              <mu>0.2</mu>
              <mu2>0.2</mu2>
            </ode>
          </friction>
        </surface>
      </collision>
      <visual name='finger_3_visual'>
        <pose frame=''>0 0 0 0 -0 0</pose>
        <geometry>
          <mesh>
            <scale>1 1 1</scale>
            <uri>model://gripper_description/meshes/platform only visual.STL</uri>
          </mesh>
        </geometry>
        <material>
          <script>
            <name>Gazebo/Grey</name>
            <uri>file://media/materials/scripts/gazebo.material</uri>
          </script>
        </material>
      </visual>
      <visual name='finger_3_segment_link_1_visual_1'>
        <pose frame=''>0.1385 -0.007 0 1.5708 -0 0</pose>
        <geometry>
          <box>
            <size>0.019 0.028 0.0009</size>
          </box>
        </geometry>
        <material>
          <script>
            <name>Gazebo/Grey</name>
            <uri>file://media/materials/scripts/gazebo.material</uri>
          </script>
        </material>
      </visual>
      <velocity_decay/>
      <gravity>1</gravity>
      <velocity_decay/>
    </link>
    <joint name='finger_3_revolute_joint' type='revolute'>
      <child>finger_3</child>
      <parent>finger_3_intermediate</parent>
      <axis>
        <xyz>0 0 1</xyz>
        <limit>
          <lower>-0.7</lower>
          <upper>0.7</upper>
          <effort>40</effort>
          <velocity>0.1</velocity>
        </limit>
        <dynamics>
          <damping>1</damping>
          <friction>0</friction>
          <spring_reference>0</spring_reference>
          <spring_stiffness>0</spring_stiffness>
        </dynamics>
        <use_parent_model_frame>0</use_parent_model_frame>
      </axis>
    </joint>
    <link name='finger_3_segment_link_2'>
      <pose frame=''>0.094762 0.001812 0.635 2.87979 1.57079 -3.14159</pose>
      <inertial>
        <pose frame=''>0 0 0 0 -0 0</pose>
        <mass>0.00633333</mass>
        <inertia>
          <ixx>4.14205e-07</ixx>
          <ixy>0</ixy>
          <ixz>0</ixz>
          <iyy>7.62539e-07</iyy>
          <iyz>0</iyz>
          <izz>1.17589e-06</izz>
        </inertia>
      </inertial>
      <collision name='finger_3_segment_link_2_collision'>
        <pose frame=''>0.0095 0 0 0 -0 0</pose>
        <geometry>
          <box>
            <size>0.019 0.028 0.0009</size>
          </box>
        </geometry>
        <surface>
          <contact>
            <ode>
              <max_vel>0</max_vel>
              <min_depth>0.001</min_depth>
            </ode>
          </contact>
          <friction>
            <ode>
              <mu>0.1</mu>
              <mu2>0.1</mu2>
            </ode>
          </friction>
        </surface>
      </collision>
      <visual name='finger_3_segment_link_2_visual'>
        <pose frame=''>0.0095 0 0 0 -0 0</pose>
        <geometry>
          <box>
            <size>0.019 0.028 0.0009</size>
          </box>
        </geometry>
        <material>
          <script>
            <name>Gazebo/Orange</name>
            <uri>file://media/materials/scripts/gazebo.material</uri>
          </script>
        </material>
      </visual>
      <gravity>1</gravity>
      <velocity_decay/>
    </link>
    <joint name='finger_3_segment_joint_1' type='revolute'>
      <child>finger_3_segment_link_2</child>
      <parent>finger_3</parent>
      <axis>
        <xyz>0 1 0</xyz>
        <limit>
          <lower>-1</lower>
          <upper>1</upper>
          <effort>1000</effort>
          <velocity>1</velocity>
        </limit>
        <dynamics>
          <damping>0.001</damping>
          <friction>0</friction>
          <spring_reference>0</spring_reference>
          <spring_stiffness>3</spring_stiffness>
        </dynamics>
        <use_parent_model_frame>0</use_parent_model_frame>
      </axis>
      <physics>
        <provide_feedback>1</provide_feedback>
        <ode>
          <provide_feedback>1</provide_feedback>
          <implicit_spring_damper>1</implicit_spring_damper>
          <cfm_damping>1</cfm_damping>
          <limit>
            <cfm>0</cfm>
            <erp>0.2</erp>
          </limit>
        </ode>
      </physics>
    </joint>
    <link name='finger_3_segment_link_3'>
      <pose frame=''>0.094762 0.001812 0.616 2.87979 1.57079 -3.14159</pose>
      <inertial>
        <pose frame=''>0 0 0 0 -0 0</pose>
        <mass>0.00633333</mass>
        <inertia>
          <ixx>4.14205e-07</ixx>
          <ixy>0</ixy>
          <ixz>0</ixz>
          <iyy>7.62539e-07</iyy>
          <iyz>0</iyz>
          <izz>1.17589e-06</izz>
        </inertia>
      </inertial>
      <collision name='finger_3_segment_link_3_collision'>
        <pose frame=''>0.0095 0 0 0 -0 0</pose>
        <geometry>
          <box>
            <size>0.019 0.028 0.0009</size>
          </box>
        </geometry>
        <surface>
          <contact>
            <ode>
              <max_vel>0</max_vel>
              <min_depth>0.001</min_depth>
            </ode>
          </contact>
          <friction>
            <ode>
              <mu>0.1</mu>
              <mu2>0.1</mu2>
            </ode>
          </friction>
        </surface>
      </collision>
      <visual name='finger_3_segment_link_3_visual'>
        <pose frame=''>0.0095 0 0 0 -0 0</pose>
        <geometry>
          <box>
            <size>0.019 0.028 0.0009</size>
          </box>
        </geometry>
        <material>
          <script>
            <name>Gazebo/Orange</name>
            <uri>file://media/materials/scripts/gazebo.material</uri>
          </script>
        </material>
      </visual>
      <gravity>1</gravity>
      <velocity_decay/>
    </link>
    <joint name='finger_3_segment_joint_2' type='revolute'>
      <child>finger_3_segment_link_3</child>
      <parent>finger_3_segment_link_2</parent>
      <axis>
        <xyz>0 1 0</xyz>
        <limit>
          <lower>-1</lower>
          <upper>1</upper>
          <effort>1000</effort>
          <velocity>1</velocity>
        </limit>
        <dynamics>
          <damping>0.001</damping>
          <friction>0</friction>
          <spring_reference>0</spring_reference>
          <spring_stiffness>3</spring_stiffness>
        </dynamics>
        <use_parent_model_frame>0</use_parent_model_frame>
      </axis>
      <physics>
        <provide_feedback>1</provide_feedback>
        <ode>
          <provide_feedback>1</provide_feedback>
          <implicit_spring_damper>1</implicit_spring_damper>
          <cfm_damping>1</cfm_damping>
          <limit>
            <cfm>0</cfm>
            <erp>0.2</erp>
          </limit>
        </ode>
      </physics>
    </joint>
    <link name='finger_3_segment_link_4'>
      <pose frame=''>0.094762 0.001812 0.597 2.87979 1.57079 -3.14159</pose>
      <inertial>
        <pose frame=''>0 0 0 0 -0 0</pose>
        <mass>0.00633333</mass>
        <inertia>
          <ixx>4.14205e-07</ixx>
          <ixy>0</ixy>
          <ixz>0</ixz>
          <iyy>7.62539e-07</iyy>
          <iyz>0</iyz>
          <izz>1.17589e-06</izz>
        </inertia>
      </inertial>
      <collision name='finger_3_segment_link_4_collision'>
        <pose frame=''>0.0095 0 0 0 -0 0</pose>
        <geometry>
          <box>
            <size>0.019 0.028 0.0009</size>
          </box>
        </geometry>
        <surface>
          <contact>
            <ode>
              <max_vel>0</max_vel>
              <min_depth>0.001</min_depth>
            </ode>
          </contact>
          <friction>
            <ode>
              <mu>0.1</mu>
              <mu2>0.1</mu2>
            </ode>
          </friction>
        </surface>
      </collision>
      <visual name='finger_3_segment_link_4_visual'>
        <pose frame=''>0.0095 0 0 0 -0 0</pose>
        <geometry>
          <box>
            <size>0.019 0.028 0.0009</size>
          </box>
        </geometry>
        <material>
          <script>
            <name>Gazebo/Orange</name>
            <uri>file://media/materials/scripts/gazebo.material</uri>
          </script>
        </material>
      </visual>
      <gravity>1</gravity>
      <velocity_decay/>
    </link>
    <joint name='finger_3_segment_joint_3' type='revolute'>
      <child>finger_3_segment_link_4</child>
      <parent>finger_3_segment_link_3</parent>
      <axis>
        <xyz>0 1 0</xyz>
        <limit>
          <lower>-1</lower>
          <upper>1</upper>
          <effort>1000</effort>
          <velocity>1</velocity>
        </limit>
        <dynamics>
          <damping>0.001</damping>
          <friction>0</friction>
          <spring_reference>0</spring_reference>
          <spring_stiffness>3</spring_stiffness>
        </dynamics>
        <use_parent_model_frame>0</use_parent_model_frame>
      </axis>
      <physics>
        <provide_feedback>1</provide_feedback>
        <ode>
          <provide_feedback>1</provide_feedback>
          <implicit_spring_damper>1</implicit_spring_damper>
          <cfm_damping>1</cfm_damping>
          <limit>
            <cfm>0</cfm>
            <erp>0.2</erp>
          </limit>
        </ode>
      </physics>
    </joint>
    <link name='finger_3_segment_link_5'>
      <pose frame=''>0.094762 0.001812 0.578 2.87979 1.57079 -3.14159</pose>
      <inertial>
        <pose frame=''>0 0 0 0 -0 0</pose>
        <mass>0.00633333</mass>
        <inertia>
          <ixx>4.14205e-07</ixx>
          <ixy>0</ixy>
          <ixz>0</ixz>
          <iyy>7.62539e-07</iyy>
          <iyz>0</iyz>
          <izz>1.17589e-06</izz>
        </inertia>
      </inertial>
      <collision name='finger_3_segment_link_5_collision'>
        <pose frame=''>0.0095 0 0 0 -0 0</pose>
        <geometry>
          <box>
            <size>0.019 0.028 0.0009</size>
          </box>
        </geometry>
        <surface>
          <contact>
            <ode>
              <max_vel>0</max_vel>
              <min_depth>0.001</min_depth>
            </ode>
          </contact>
          <friction>
            <ode>
              <mu>0.1</mu>
              <mu2>0.1</mu2>
            </ode>
          </friction>
        </surface>
      </collision>
      <visual name='finger_3_segment_link_5_visual'>
        <pose frame=''>0.0095 0 0 0 -0 0</pose>
        <geometry>
          <box>
            <size>0.019 0.028 0.0009</size>
          </box>
        </geometry>
        <material>
          <script>
            <name>Gazebo/Orange</name>
            <uri>file://media/materials/scripts/gazebo.material</uri>
          </script>
        </material>
      </visual>
      <gravity>1</gravity>
      <velocity_decay/>
    </link>
    <joint name='finger_3_segment_joint_4' type='revolute'>
      <child>finger_3_segment_link_5</child>
      <parent>finger_3_segment_link_4</parent>
      <axis>
        <xyz>0 1 0</xyz>
        <limit>
          <lower>-1</lower>
          <upper>1</upper>
          <effort>1000</effort>
          <velocity>1</velocity>
        </limit>
        <dynamics>
          <damping>0.001</damping>
          <friction>0</friction>
          <spring_reference>0</spring_reference>
          <spring_stiffness>3</spring_stiffness>
        </dynamics>
        <use_parent_model_frame>0</use_parent_model_frame>
      </axis>
      <physics>
        <provide_feedback>1</provide_feedback>
        <ode>
          <provide_feedback>1</provide_feedback>
          <implicit_spring_damper>1</implicit_spring_damper>
          <cfm_damping>1</cfm_damping>
          <limit>
            <cfm>0</cfm>
            <erp>0.2</erp>
          </limit>
        </ode>
      </physics>
    </joint>
    <link name='finger_3_segment_link_6'>
      <pose frame=''>0.094762 0.001812 0.559 2.87979 1.57079 -3.14159</pose>
      <inertial>
        <pose frame=''>0 0 0 0 -0 0</pose>
        <mass>0.00633333</mass>
        <inertia>
          <ixx>4.14205e-07</ixx>
          <ixy>0</ixy>
          <ixz>0</ixz>
          <iyy>7.62539e-07</iyy>
          <iyz>0</iyz>
          <izz>1.17589e-06</izz>
        </inertia>
      </inertial>
      <collision name='finger_3_segment_link_6_collision'>
        <pose frame=''>0.0095 0 0 0 -0 0</pose>
        <geometry>
          <box>
            <size>0.019 0.028 0.0009</size>
          </box>
        </geometry>
        <surface>
          <contact>
            <ode>
              <max_vel>0</max_vel>
              <min_depth>0.001</min_depth>
            </ode>
          </contact>
          <friction>
            <ode>
              <mu>0.1</mu>
              <mu2>0.1</mu2>
            </ode>
          </friction>
        </surface>
      </collision>
      <visual name='finger_3_segment_link_6_visual'>
        <pose frame=''>0.0095 0 0 0 -0 0</pose>
        <geometry>
          <box>
            <size>0.019 0.028 0.0009</size>
          </box>
        </geometry>
        <material>
          <script>
            <name>Gazebo/Orange</name>
            <uri>file://media/materials/scripts/gazebo.material</uri>
          </script>
        </material>
      </visual>
      <gravity>1</gravity>
      <velocity_decay/>
    </link>
    <joint name='finger_3_segment_joint_5' type='revolute'>
      <child>finger_3_segment_link_6</child>
      <parent>finger_3_segment_link_5</parent>
      <axis>
        <xyz>0 1 0</xyz>
        <limit>
          <lower>-1</lower>
          <upper>1</upper>
          <effort>1000</effort>
          <velocity>1</velocity>
        </limit>
        <dynamics>
          <damping>0.001</damping>
          <friction>0</friction>
          <spring_reference>0</spring_reference>
          <spring_stiffness>3</spring_stiffness>
        </dynamics>
        <use_parent_model_frame>0</use_parent_model_frame>
      </axis>
      <physics>
        <provide_feedback>1</provide_feedback>
        <ode>
          <provide_feedback>1</provide_feedback>
          <implicit_spring_damper>1</implicit_spring_damper>
          <cfm_damping>1</cfm_damping>
          <limit>
            <cfm>0</cfm>
            <erp>0.2</erp>
          </limit>
        </ode>
      </physics>
    </joint>
    <link name='finger_3_segment_link_7'>
      <pose frame=''>0.094762 0.001812 0.54 2.87979 1.57079 -3.14159</pose>
      <inertial>
        <pose frame=''>0 0 0 0 -0 0</pose>
        <mass>0.00633333</mass>
        <inertia>
          <ixx>4.14205e-07</ixx>
          <ixy>0</ixy>
          <ixz>0</ixz>
          <iyy>7.62539e-07</iyy>
          <iyz>0</iyz>
          <izz>1.17589e-06</izz>
        </inertia>
      </inertial>
      <collision name='finger_3_segment_link_7_collision'>
        <pose frame=''>0.0095 0 0 0 -0 0</pose>
        <geometry>
          <box>
            <size>0.019 0.028 0.0009</size>
          </box>
        </geometry>
        <surface>
          <contact>
            <ode>
              <max_vel>0</max_vel>
              <min_depth>0.001</min_depth>
            </ode>
          </contact>
          <friction>
            <ode>
              <mu>0.1</mu>
              <mu2>0.1</mu2>
            </ode>
          </friction>
        </surface>
      </collision>
      <visual name='finger_3_segment_link_7_visual'>
        <pose frame=''>0.0095 0 0 0 -0 0</pose>
        <geometry>
          <box>
            <size>0.019 0.028 0.0009</size>
          </box>
        </geometry>
        <material>
          <script>
            <name>Gazebo/Orange</name>
            <uri>file://media/materials/scripts/gazebo.material</uri>
          </script>
        </material>
      </visual>
      <gravity>1</gravity>
      <velocity_decay/>
    </link>
    <joint name='finger_3_segment_joint_6' type='revolute'>
      <child>finger_3_segment_link_7</child>
      <parent>finger_3_segment_link_6</parent>
      <axis>
        <xyz>0 1 0</xyz>
        <limit>
          <lower>-1</lower>
          <upper>1</upper>
          <effort>1000</effort>
          <velocity>1</velocity>
        </limit>
        <dynamics>
          <damping>0.001</damping>
          <friction>0</friction>
          <spring_reference>0</spring_reference>
          <spring_stiffness>3</spring_stiffness>
        </dynamics>
        <use_parent_model_frame>0</use_parent_model_frame>
      </axis>
      <physics>
        <provide_feedback>1</provide_feedback>
        <ode>
          <provide_feedback>1</provide_feedback>
          <implicit_spring_damper>1</implicit_spring_damper>
          <cfm_damping>1</cfm_damping>
          <limit>
            <cfm>0</cfm>
            <erp>0.2</erp>
          </limit>
        </ode>
      </physics>
    </joint>
    <link name='finger_3_segment_link_8'>
      <pose frame=''>0.094762 0.001812 0.521 2.87979 1.57079 -3.14159</pose>
      <inertial>
        <pose frame=''>0 0 0 0 -0 0</pose>
        <mass>0.00633333</mass>
        <inertia>
          <ixx>4.14205e-07</ixx>
          <ixy>0</ixy>
          <ixz>0</ixz>
          <iyy>7.62539e-07</iyy>
          <iyz>0</iyz>
          <izz>1.17589e-06</izz>
        </inertia>
      </inertial>
      <collision name='finger_3_segment_link_8_collision'>
        <pose frame=''>0.0095 0 0 0 -0 0</pose>
        <geometry>
          <box>
            <size>0.019 0.028 0.0009</size>
          </box>
        </geometry>
        <surface>
          <contact>
            <ode>
              <max_vel>0</max_vel>
              <min_depth>0.001</min_depth>
            </ode>
          </contact>
          <friction>
            <ode>
              <mu>0.1</mu>
              <mu2>0.1</mu2>
            </ode>
          </friction>
        </surface>
      </collision>
      <visual name='finger_3_segment_link_8_visual'>
        <pose frame=''>0.0095 0 0 0 -0 0</pose>
        <geometry>
          <box>
            <size>0.019 0.028 0.0009</size>
          </box>
        </geometry>
        <material>
          <script>
            <name>Gazebo/Orange</name>
            <uri>file://media/materials/scripts/gazebo.material</uri>
          </script>
        </material>
      </visual>
      <gravity>1</gravity>
      <velocity_decay/>
    </link>
    <joint name='finger_3_segment_joint_7' type='revolute'>
      <child>finger_3_segment_link_8</child>
      <parent>finger_3_segment_link_7</parent>
      <axis>
        <xyz>0 1 0</xyz>
        <limit>
          <lower>-1</lower>
          <upper>1</upper>
          <effort>1000</effort>
          <velocity>1</velocity>
        </limit>
        <dynamics>
          <damping>0.001</damping>
          <friction>0</friction>
          <spring_reference>0</spring_reference>
          <spring_stiffness>3</spring_stiffness>
        </dynamics>
        <use_parent_model_frame>0</use_parent_model_frame>
      </axis>
      <physics>
        <provide_feedback>1</provide_feedback>
        <ode>
          <provide_feedback>1</provide_feedback>
          <implicit_spring_damper>1</implicit_spring_damper>
          <cfm_damping>1</cfm_damping>
          <limit>
            <cfm>0</cfm>
            <erp>0.2</erp>
          </limit>
        </ode>
      </physics>
    </joint>
    <link name='finger_3_segment_link_9'>
      <pose frame=''>0.094762 0.001812 0.502 2.87979 1.57079 -3.14159</pose>
      <inertial>
        <pose frame=''>0 0 0 0 -0 0</pose>
        <mass>0.00633333</mass>
        <inertia>
          <ixx>4.14205e-07</ixx>
          <ixy>0</ixy>
          <ixz>0</ixz>
          <iyy>7.62539e-07</iyy>
          <iyz>0</iyz>
          <izz>1.17589e-06</izz>
        </inertia>
      </inertial>
      <collision name='finger_3_segment_link_9_collision'>
        <pose frame=''>0.0095 0 0 0 -0 0</pose>
        <geometry>
          <box>
            <size>0.019 0.028 0.0009</size>
          </box>
        </geometry>
        <surface>
          <contact>
            <ode>
              <max_vel>0</max_vel>
              <min_depth>0.001</min_depth>
            </ode>
          </contact>
          <friction>
            <ode>
              <mu>0.1</mu>
              <mu2>0.1</mu2>
            </ode>
          </friction>
        </surface>
      </collision>
      <visual name='finger_3_segment_link_9_visual'>
        <pose frame=''>0.0095 0 0 0 -0 0</pose>
        <geometry>
          <box>
            <size>0.019 0.028 0.0009</size>
          </box>
        </geometry>
        <material>
          <script>
            <name>Gazebo/Orange</name>
            <uri>file://media/materials/scripts/gazebo.material</uri>
          </script>
        </material>
      </visual>
      <gravity>1</gravity>
      <velocity_decay/>
    </link>
    <joint name='finger_3_segment_joint_8' type='revolute'>
      <child>finger_3_segment_link_9</child>
      <parent>finger_3_segment_link_8</parent>
      <axis>
        <xyz>0 1 0</xyz>
        <limit>
          <lower>-1</lower>
          <upper>1</upper>
          <effort>1000</effort>
          <velocity>1</velocity>
        </limit>
        <dynamics>
          <damping>0.001</damping>
          <friction>0</friction>
          <spring_reference>0</spring_reference>
          <spring_stiffness>3</spring_stiffness>
        </dynamics>
        <use_parent_model_frame>0</use_parent_model_frame>
      </axis>
      <physics>
        <provide_feedback>1</provide_feedback>
        <ode>
          <provide_feedback>1</provide_feedback>
          <implicit_spring_damper>1</implicit_spring_damper>
          <cfm_damping>1</cfm_damping>
          <limit>
            <cfm>0</cfm>
            <erp>0.2</erp>
          </limit>
        </ode>
      </physics>
    </joint>
    <link name='finger_3_segment_link_10'>
      <pose frame=''>0.094762 0.001812 0.483 2.87979 1.57079 -3.14159</pose>
      <inertial>
        <pose frame=''>0.0095 0 0 0 -0 0</pose>
        <mass>0.0126667</mass>
        <inertia>
          <ixx>1.59009e-06</ixx>
          <ixy>0</ixy>
          <ixz>-4.66397e-23</ixz>
          <iyy>2.66824e-06</iyy>
          <iyz>0</iyz>
          <izz>2.73326e-06</izz>
        </inertia>
      </inertial>
      <collision name='finger_3_segment_link_10_collision'>
        <pose frame=''>0.0095 0 0 0 -0 0</pose>
        <geometry>
          <box>
            <size>0.019 0.028 0.0009</size>
          </box>
        </geometry>
        <surface>
          <contact>
            <ode>
              <max_vel>0</max_vel>
              <min_depth>0.001</min_depth>
            </ode>
          </contact>
          <friction>
            <ode>
              <mu>0.1</mu>
              <mu2>0.1</mu2>
            </ode>
          </friction>
        </surface>
      </collision>
      <collision name='finger_3_segment_link_10_fixed_joint_lump__finger_3_finger_hook_link_collision_1'>
        <pose frame=''>0.019 0 0.0175 3.14159 -1.57079 3.14159</pose>
        <geometry>
          <box>
            <size>0.035 0.028 0.0009</size>
          </box>
        </geometry>
        <surface>
          <contact>
            <ode>
              <max_vel>0</max_vel>
              <min_depth>0.001</min_depth>
            </ode>
          </contact>
          <friction>
            <ode>
              <mu>0.1</mu>
              <mu2>0.1</mu2>
            </ode>
          </friction>
        </surface>
      </collision>
      <visual name='finger_3_segment_link_10_visual'>
        <pose frame=''>0.0095 0 0 0 -0 0</pose>
        <geometry>
          <box>
            <size>0.019 0.028 0.0009</size>
          </box>
        </geometry>
        <material>
          <script>
            <name>Gazebo/Orange</name>
            <uri>file://media/materials/scripts/gazebo.material</uri>
          </script>
        </material>
      </visual>
      <visual name='finger_3_segment_link_10_fixed_joint_lump__finger_3_finger_hook_link_visual_1'>
        <pose frame=''>0.019 0 0.0175 3.14159 -1.57079 3.14159</pose>
        <geometry>
          <box>
            <size>0.035 0.028 0.0009</size>
          </box>
        </geometry>
        <material>
          <script>
            <name>Gazebo/Orange</name>
            <uri>file://media/materials/scripts/gazebo.material</uri>
          </script>
        </material>
      </visual>
      <velocity_decay/>
      <gravity>1</gravity>
      <velocity_decay/>
    </link>
    <joint name='finger_3_segment_joint_9' type='revolute'>
      <child>finger_3_segment_link_10</child>
      <parent>finger_3_segment_link_9</parent>
      <axis>
        <xyz>0 1 0</xyz>
        <limit>
          <lower>-1</lower>
          <upper>1</upper>
          <effort>1000</effort>
          <velocity>1</velocity>
        </limit>
        <dynamics>
          <damping>0.001</damping>
          <friction>0</friction>
          <spring_reference>0</spring_reference>
          <spring_stiffness>3</spring_stiffness>
        </dynamics>
        <use_parent_model_frame>0</use_parent_model_frame>
      </axis>
      <physics>
        <provide_feedback>1</provide_feedback>
        <ode>
          <provide_feedback>1</provide_feedback>
          <implicit_spring_damper>1</implicit_spring_damper>
          <cfm_damping>1</cfm_damping>
          <limit>
            <cfm>0</cfm>
            <erp>0.2</erp>
          </limit>
        </ode>
      </physics>
    </joint>
    <link name='palm'>
      <pose frame=''>0.088 -0 0.783 -0.785403 1.57079 3.14159</pose>
      <inertial>
        <pose frame=''>0 0 0 0 -0 0</pose>
        <mass>0.05</mass>
        <inertia>
          <ixx>1e-05</ixx>
          <ixy>0</ixy>
          <ixz>0</ixz>
          <iyy>1e-05</iyy>
          <iyz>0</iyz>
          <izz>1e-05</izz>
        </inertia>
      </inertial>
      <collision name='palm_collision'>
        <pose frame=''>0 0 0 0 -0 0</pose>
        <geometry>
          <mesh>
            <scale>1 1 1</scale>
            <uri>model://gripper_description/meshes/palm collision.STL</uri>
          </mesh>
        </geometry>
        <surface>
          <contact>
            <ode/>
          </contact>
          <friction>
            <ode>
              <mu>0.2</mu>
              <mu2>0.2</mu2>
            </ode>
          </friction>
        </surface>
      </collision>
      <visual name='palm_visual'>
        <pose frame=''>0 0 0 0 -0 0</pose>
        <geometry>
          <mesh>
            <scale>1 1 1</scale>
            <uri>model://gripper_description/meshes/palm visual.STL</uri>
          </mesh>
        </geometry>
        <material>
          <script>
            <name>Gazebo/Grey</name>
            <uri>file://media/materials/scripts/gazebo.material</uri>
          </script>
        </material>
      </visual>
      <gravity>1</gravity>
      <velocity_decay/>
    </link>
    <joint name='palm_prismatic_joint' type='prismatic'>
      <child>palm</child>
      <parent>panda_link7</parent>
      <axis>
        <xyz>1 0 0</xyz>
        <limit>
          <lower>0</lower>
          <upper>0.16</upper>
          <effort>40</effort>
          <velocity>0.036</velocity>
        </limit>
        <dynamics>
          <damping>1</damping>
          <friction>0</friction>
          <spring_reference>0</spring_reference>
          <spring_stiffness>0</spring_stiffness>
        </dynamics>
        <use_parent_model_frame>0</use_parent_model_frame>
      </axis>
    </joint>
    <plugin name='gazebo_ros_control' filename='libgazebo_ros_control.so'/>
    <static>0</static>
    <plugin name='finger_controller_plugin' filename='libfinger_controller_plugin.so'/>
  </model>
</sdf>
